Workbook

Sheet 72_cij
B1: DG Granule | C1: DG Semilunar Granule | D1: DG Mossy | E1: DG AIPRIM | F1: DG Axo Axonic | G1: DG Basket | H1: DG HICAP | I1: DG HIPP | J1: DG HIPROM | K1: DG MOLAX | L1: DG MOPP | M1: DG Neurogliaform | N1: DG Total Molecular Layer | O1: CA3 Pyramidal | P1: CA3c Pyramidal | Q1: CA3 Granule | R1: CA3 Axo Axonic | S1: CA3 Basket | T1: CA3 LMR Targeting | U1: CA3 Lucidum ORAX | V1: CA3 Spiny Lucidum | W1: CA3 Mossy Fiber Associated ORDEN | X1: CA3 Trilaminar | Y1: CA2 Basket | Z1: CA2 Wide Arbor Basket | AA1: CA2 Bistratified | AB1: CA2 SP SR | AC1: CA1 Pyramidal | AD1: CA1 Radiatum Giant | AE1: CA1 Axo Axonic | AF1: CA1 Horizontal Axo Axonic | AG1: CA1 Basket | AH1: CA1 Basket CCK+ | AI1: CA1 Horizontal Basket | AJ1: CA1 Ivy | AK1: CA1 LMR | AL1: CA1 Neurogliaform | AM1: CA1 Neurogliaform Projecting | AN1: CA1 Recurrent O LM | AO1: CA1 O LMR | AP1: CA1 Oriens Alveus | AQ1: CA1 Oriens Bistratified | AR1: CA1 OR LM | AS1: CA1 Perforant Path Associated | AT1: CA1 Perforant Path Associated QuadD | AU1: CA1 Radiatum | AV1: CA1 R Receiving Apical Targeting | AW1: CA1 Schaffer Collateral Associated | AX1: CA1 SO SO | AY1: CA1 Trilaminar | AZ1: CA1 Radial Trilaminar | BA1: EC LI II Multipolar Pyramidal | BB1: EC LI II Pyramidal Fan | BC1: MEC LII III Pyramidal Multiform | BD1: MEC LII Oblique Pyramidal | BE1: MEC LII Stellate | BF1: EC LII III Pyramidal Tripolar | BG1: LEC LIII Multipolar Principal | BH1: EC LIII Pyramidal | BI1: LEC LIII Complex Pyramidal | BJ1: MEC LIII Complex Pyramidal | BK1: MEC LIII Bipolar Complex Pyramidal | BL1: EC LIII Stellate | BM1: EC LIII V Bipolar Pyramidal | BN1: EC LIV VI Deep Multipolar Principal | BO1: EC LV Deep Pyramidal | BP1: MEC LV Multipolar Pyramidal | BQ1: MEC LV Pyramidal | BR1: MEC LV Superficial Pyramidal | BS1: MEC LV VI Pyramidal Polymorphic | BT1: LEC LVI Multipolar Pyramidal | BU1: MEC LIII Superficial Trilayered Interneuron
A2: DG Granule | B2: 0 | C2: 0 | D2: 0.007771 | E2: 0.005331 | F2: 0.003907 | G2: 0.00346 | H2: 0.003335 | I2: 0.005946 | J2: 0.005372 | K2: 0.004358 | L2: 0 | M2: 0 | N2: 0.00422 | O2: 8.53e-05 | P2: 0.0003366 | Q2: 0 | R2: 0.0006667 | S2: 0.0005885 | T2: 0.0001794 | U2: 0.0001907 | V2: 0.0004899 | W2: 0.0003844 | X2: 0 | Y2: 0.002201249 | Z2: 0.001310674 | AA2: 0.001402889 | AB2: 0 | AC2: 0 | AD2: 0 | AE2: 0 | AF2: 0 | AG2: 0 | AH2: 0 | AI2: 0 | AJ2: 0 | AK2: 0 | AL2: 0 | AM2: 0 | AN2: 0 | AO2: 0 | AP2: 0 | AQ2: 0 | AR2: 0 | AS2: 0 | AT2: 0 | AU2: 0 | AV2: 0 | AW2: 0 | AX2: 0 | AY2: 0 | AZ2: 0 | BA2: 0 | BB2: 0 | BC2: 0 | BD2: 0 | BE2: 0 | BF2: 0 | BG2: 0 | BH2: 0 | BI2: 0 | BJ2: 0 | BK2: 0 | BL2: 0 | BM2: 0 | BN2: 0 | BO2: 0 | BP2: 0 | BQ2: 0 | BR2: 0 | BS2: 0 | BT2: 0 | BU2: 0
A3: DG Semilunar Granule | B3: 0.0002463 | C3: 0.000279 | D3: 0.00581 | E3: 0.005796 | F3: 0.004204 | G3: 0.003812 | H3: 0.004227 | I3: 0.003702 | J3: 0.007157 | K3: 0.004599 | L3: 0 | M3: 0 | N3: 0.002668 | O3: 0.0001301 | P3: 0.0002067 | Q3: 0 | R3: 0.0004636 | S3: 0.0003222 | T3: 0.0001075 | U3: 0.0004143 | V3: 0.0006109 | W3: 0.0002087 | X3: 0 | Y3: 0 | Z3: 0 | AA3: 0 | AB3: 0 | AC3: 0 | AD3: 0 | AE3: 0 | AF3: 0 | AG3: 0 | AH3: 0 | AI3: 0 | AJ3: 0 | AK3: 0 | AL3: 0 | AM3: 0 | AN3: 0 | AO3: 0 | AP3: 0 | AQ3: 0 | AR3: 0 | AS3: 0 | AT3: 0 | AU3: 0 | AV3: 0 | AW3: 0 | AX3: 0 | AY3: 0 | AZ3: 0 | BA3: 0 | BB3: 0 | BC3: 0 | BD3: 0 | BE3: 0 | BF3: 0 | BG3: 0 | BH3: 0 | BI3: 0 | BJ3: 0 | BK3: 0 | BL3: 0 | BM3: 0 | BN3: 0 | BO3: 0 | BP3: 0 | BQ3: 0 | BR3: 0 | BS3: 0 | BT3: 0 | BU3: 0
A4: DG Mossy | B4: 0.002374 | C4: 0.002166 | D4: 0.01217 | E4: 0.01378 | F4: 0.01325 | G4: 0.01174 | H4: 0.01111 | I4: 0.009928 | J4: 0.01524 | K4: 0.01345 | L4: 0 | M4: 0 | N4: 0.01157 | O4: 0 | P4: 0 | Q4: 0 | R4: 0 | S4: 0 | T4: 0 | U4: 0 | V4: 0 | W4: 0 | X4: 0 | Y4: 0 | Z4: 0 | AA4: 0 | AB4: 0 | AC4: 0 | AD4: 0 | AE4: 0 | AF4: 0 | AG4: 0 | AH4: 0 | AI4: 0 | AJ4: 0 | AK4: 0 | AL4: 0 | AM4: 0 | AN4: 0 | AO4: 0 | AP4: 0 | AQ4: 0 | AR4: 0 | AS4: 0 | AT4: 0 | AU4: 0 | AV4: 0 | AW4: 0 | AX4: 0 | AY4: 0 | AZ4: 0 | BA4: 0 | BB4: 0 | BC4: 0 | BD4: 0 | BE4: 0 | BF4: 0 | BG4: 0 | BH4: 0 | BI4: 0 | BJ4: 0 | BK4: 0 | BL4: 0 | BM4: 0 | BN4: 0 | BO4: 0 | BP4: 0 | BQ4: 0 | BR4: 0 | BS4: 0 | BT4: 0 | BU4: 0
A5: DG AIPRIM | B5: 0.00419 | C5: 0.004097 | D5: 0.007415 | E5: 0.0138 | F5: 0.01226 | G5: 0.01166 | H5: 0.01198 | I5: 0.00524 | J5: 0.01658 | K5: 0.01107 | L5: 0 | M5: 0 | N5: 0.007942 | O5: 0 | P5: 0 | Q5: 0 | R5: 0 | S5: 0 | T5: 0 | U5: 0 | V5: 0 | W5: 0 | X5: 0 | Y5: 0 | Z5: 0 | AA5: 0 | AB5: 0 | AC5: 0 | AD5: 0 | AE5: 0 | AF5: 0 | AG5: 0 | AH5: 0 | AI5: 0 | AJ5: 0 | AK5: 0 | AL5: 0 | AM5: 0 | AN5: 0 | AO5: 0 | AP5: 0 | AQ5: 0 | AR5: 0 | AS5: 0 | AT5: 0 | AU5: 0 | AV5: 0 | AW5: 0 | AX5: 0 | AY5: 0 | AZ5: 0 | BA5: 0 | BB5: 0 | BC5: 0 | BD5: 0 | BE5: 0 | BF5: 0 | BG5: 0 | BH5: 0 | BI5: 0 | BJ5: 0 | BK5: 0 | BL5: 0 | BM5: 0 | BN5: 0 | BO5: 0 | BP5: 0 | BQ5: 0 | BR5: 0 | BS5: 0 | BT5: 0 | BU5: 0
A6: DG Axo Axonic | B6: 0.001430284 | C6: 0 | D6: 0.053814974 | E6: 0 | F6: 0 | G6: 0 | H6: 0 | I6: 0 | J6: 0 | K6: 0 | L6: 0 | M6: 0 | N6: 0 | O6: 0 | P6: 0 | Q6: 0 | R6: 0 | S6: 0 | T6: 0 | U6: 0 | V6: 0 | W6: 0 | X6: 0 | Y6: 0 | Z6: 0 | AA6: 0 | AB6: 0 | AC6: 0 | AD6: 0 | AE6: 0 | AF6: 0 | AG6: 0 | AH6: 0 | AI6: 0 | AJ6: 0 | AK6: 0 | AL6: 0 | AM6: 0 | AN6: 0 | AO6: 0 | AP6: 0 | AQ6: 0 | AR6: 0 | AS6: 0 | AT6: 0 | AU6: 0 | AV6: 0 | AW6: 0 | AX6: 0 | AY6: 0 | AZ6: 0 | BA6: 0 | BB6: 0 | BC6: 0 | BD6: 0 | BE6: 0 | BF6: 0 | BG6: 0 | BH6: 0 | BI6: 0 | BJ6: 0 | BK6: 0 | BL6: 0 | BM6: 0 | BN6: 0 | BO6: 0 | BP6: 0 | BQ6: 0 | BR6: 0 | BS6: 0 | BT6: 0 | BU6: 0
A7: DG Basket | B7: 0.18644262 | C7: 0 | D7: 0 | E7: 0 | F7: 0.18644262 | G7: 0.18644262 | H7: 0.18644262 | I7: 0.18644262 | J7: 0 | K7: 0.18644262 | L7: 0 | M7: 0 | N7: 0.18644262 | O7: 0 | P7: 0 | Q7: 0 | R7: 0 | S7: 0 | T7: 0 | U7: 0 | V7: 0 | W7: 0 | X7: 0 | Y7: 0 | Z7: 0 | AA7: 0 | AB7: 0 | AC7: 0 | AD7: 0 | AE7: 0 | AF7: 0 | AG7: 0 | AH7: 0 | AI7: 0 | AJ7: 0 | AK7: 0 | AL7: 0 | AM7: 0 | AN7: 0 | AO7: 0 | AP7: 0 | AQ7: 0 | AR7: 0 | AS7: 0 | AT7: 0 | AU7: 0 | AV7: 0 | AW7: 0 | AX7: 0 | AY7: 0 | AZ7: 0 | BA7: 0 | BB7: 0 | BC7: 0 | BD7: 0 | BE7: 0 | BF7: 0 | BG7: 0 | BH7: 0 | BI7: 0 | BJ7: 0 | BK7: 0 | BL7: 0 | BM7: 0 | BN7: 0 | BO7: 0 | BP7: 0 | BQ7: 0 | BR7: 0 | BS7: 0 | BT7: 0 | BU7: 0
A8: DG HICAP | B8: 0.001758 | C8: 0.001794 | D8: 0 | E8: 0.001567 | F8: 0.001868 | G8: 0.001591 | H8: 0.001873 | I8: 0 | J8: 0.002828 | K8: 0.002614 | L8: 0 | M8: 0 | N8: 0.001353 | O8: 0 | P8: 0 | Q8: 0 | R8: 0 | S8: 0 | T8: 0 | U8: 0 | V8: 0 | W8: 0 | X8: 0 | Y8: 0 | Z8: 0 | AA8: 0 | AB8: 0 | AC8: 0 | AD8: 0 | AE8: 0 | AF8: 0 | AG8: 0 | AH8: 0 | AI8: 0 | AJ8: 0 | AK8: 0 | AL8: 0 | AM8: 0 | AN8: 0 | AO8: 0 | AP8: 0 | AQ8: 0 | AR8: 0 | AS8: 0 | AT8: 0 | AU8: 0 | AV8: 0 | AW8: 0 | AX8: 0 | AY8: 0 | AZ8: 0 | BA8: 0 | BB8: 0 | BC8: 0 | BD8: 0 | BE8: 0 | BF8: 0 | BG8: 0 | BH8: 0 | BI8: 0 | BJ8: 0 | BK8: 0 | BL8: 0 | BM8: 0 | BN8: 0 | BO8: 0 | BP8: 0 | BQ8: 0 | BR8: 0 | BS8: 0 | BT8: 0 | BU8: 0
A9: DG HIPP | B9: 0.005952 | C9: 0.006541 | D9: 0 | E9: 0.004287 | F9: 0.007243 | G9: 0.006093 | H9: 0.004708 | I9: 0 | J9: 0 | K9: 0.004418 | L9: 0.005529 | M9: 0.004257 | N9: 0.003228 | O9: 0 | P9: 0 | Q9: 0 | R9: 0 | S9: 0 | T9: 0 | U9: 0 | V9: 0 | W9: 0 | X9: 0 | Y9: 0 | Z9: 0 | AA9: 0 | AB9: 0 | AC9: 0 | AD9: 0 | AE9: 0 | AF9: 0 | AG9: 0 | AH9: 0 | AI9: 0 | AJ9: 0 | AK9: 0 | AL9: 0 | AM9: 0.004042 | AN9: 0 | AO9: 0 | AP9: 0 | AQ9: 0 | AR9: 0 | AS9: 0 | AT9: 0 | AU9: 0 | AV9: 0 | AW9: 0 | AX9: 0 | AY9: 0 | AZ9: 0 | BA9: 0 | BB9: 0 | BC9: 0 | BD9: 0 | BE9: 0 | BF9: 0 | BG9: 0 | BH9: 0 | BI9: 0 | BJ9: 0 | BK9: 0 | BL9: 0 | BM9: 0 | BN9: 0 | BO9: 0 | BP9: 0 | BQ9: 0 | BR9: 0 | BS9: 0 | BT9: 0 | BU9: 0
A10: DG HIPROM | B10: 0.006383 | C10: 0.006684 | D10: 0.009444 | E10: 0.0198 | F10: 0.01906 | G10: 0.01776 | H10: 0.01772 | I10: 0.007118 | J10: 0.01893 | K10: 0.01503 | L10: 0.002386 | M10: 0.001807 | N10: 0.01111 | O10: 0.005005 | P10: 0.005861 | Q10: 0.00019119 | R10: 0.006575 | S10: 0.005949 | T10: 0.001614 | U10: 0.002504 | V10: 0.004649 | W10: 0.006449 | X10: 0.004534 | Y10: 0 | Z10: 0.000903952 | AA10: 0 | AB10: 0 | AC10: 0 | AD10: 0 | AE10: 0 | AF10: 0 | AG10: 0 | AH10: 0 | AI10: 0 | AJ10: 0 | AK10: 0 | AL10: 0 | AM10: 0.001756 | AN10: 0 | AO10: 0 | AP10: 0 | AQ10: 0 | AR10: 0 | AS10: 0 | AT10: 0 | AU10: 0 | AV10: 0 | AW10: 0 | AX10: 0 | AY10: 0 | AZ10: 0 | BA10: 0 | BB10: 0 | BC10: 0 | BD10: 0 | BE10: 0 | BF10: 0 | BG10: 0 | BH10: 0 | BI10: 0 | BJ10: 0 | BK10: 0 | BL10: 0 | BM10: 0 | BN10: 0 | BO10: 0 | BP10: 0 | BQ10: 0 | BR10: 0 | BS10: 0 | BT10: 0 | BU10: 0
A11: DG MOLAX | B11: 0.005739 | C11: 0.006043 | D11: 0 | E11: 0.004612 | F11: 0.006436 | G11: 0.005294 | H11: 0.0051 | I11: 0 | J11: 0.002558 | K11: 0.006067 | L11: 0.002425 | M11: 0.001886 | N11: 0.003874 | O11: 0 | P11: 0 | Q11: 0 | R11: 0 | S11: 0 | T11: 0 | U11: 0 | V11: 0 | W11: 0 | X11: 0 | Y11: 0 | Z11: 0 | AA11: 0 | AB11: 0 | AC11: 0 | AD11: 0 | AE11: 0 | AF11: 0 | AG11: 0 | AH11: 0 | AI11: 0 | AJ11: 0 | AK11: 0 | AL11: 0 | AM11: 0.001853 | AN11: 0 | AO11: 0 | AP11: 0 | AQ11: 0 | AR11: 0 | AS11: 0 | AT11: 0 | AU11: 0 | AV11: 0 | AW11: 0 | AX11: 0 | AY11: 0 | AZ11: 0 | BA11: 0 | BB11: 0 | BC11: 0 | BD11: 0 | BE11: 0 | BF11: 0 | BG11: 0 | BH11: 0 | BI11: 0 | BJ11: 0 | BK11: 0 | BL11: 0 | BM11: 0 | BN11: 0 | BO11: 0 | BP11: 0 | BQ11: 0 | BR11: 0 | BS11: 0 | BT11: 0 | BU11: 0
A12: DG MOPP | B12: 0.003394 | C12: 0.003671 | D12: 0 | E12: 0.002733 | F12: 0.003911 | G12: 0.003103 | H12: 0.002855 | I12: 0 | J12: 0 | K12: 0.003253 | L12: 0.00279 | M12: 0.002492 | N12: 0.002345 | O12: 0 | P12: 0 | Q12: 0 | R12: 0 | S12: 0 | T12: 0 | U12: 0 | V12: 0 | W12: 0 | X12: 0 | Y12: 0 | Z12: 0 | AA12: 0 | AB12: 0 | AC12: 0 | AD12: 0 | AE12: 0 | AF12: 0 | AG12: 0 | AH12: 0 | AI12: 0 | AJ12: 0 | AK12: 0 | AL12: 0 | AM12: 0.002597 | AN12: 0 | AO12: 0 | AP12: 0 | AQ12: 0 | AR12: 0 | AS12: 0 | AT12: 0 | AU12: 0 | AV12: 0 | AW12: 0 | AX12: 0 | AY12: 0 | AZ12: 0 | BA12: 0 | BB12: 0 | BC12: 0 | BD12: 0 | BE12: 0 | BF12: 0 | BG12: 0 | BH12: 0 | BI12: 0 | BJ12: 0 | BK12: 0 | BL12: 0 | BM12: 0 | BN12: 0 | BO12: 0 | BP12: 0 | BQ12: 0 | BR12: 0 | BS12: 0 | BT12: 0 | BU12: 0
A13: DG Neurogliaform | B13: 0.0007226 | C13: 0.0009182 | D13: 0 | E13: 0.0003661 | F13: 0.001099 | G13: 0.0004149 | H13: 0.0003998 | I13: 0 | J13: 0 | K13: 0.0007206 | L13: 0.0001558 | M13: 8.45e-05 | N13: 0.000252 | O13: 0 | P13: 0 | Q13: 0 | R13: 0 | S13: 0 | T13: 0 | U13: 0 | V13: 0 | W13: 0 | X13: 0 | Y13: 0 | Z13: 0 | AA13: 0 | AB13: 0 | AC13: 0 | AD13: 0 | AE13: 0 | AF13: 0 | AG13: 0 | AH13: 0 | AI13: 0 | AJ13: 0 | AK13: 0 | AL13: 0 | AM13: 0.0002827 | AN13: 0 | AO13: 0 | AP13: 0 | AQ13: 0 | AR13: 0 | AS13: 0 | AT13: 0 | AU13: 0 | AV13: 0 | AW13: 0 | AX13: 0 | AY13: 0 | AZ13: 0 | BA13: 0 | BB13: 0 | BC13: 0 | BD13: 0 | BE13: 0 | BF13: 0 | BG13: 0 | BH13: 0 | BI13: 0 | BJ13: 0 | BK13: 0 | BL13: 0 | BM13: 0 | BN13: 0 | BO13: 0 | BP13: 0 | BQ13: 0 | BR13: 0 | BS13: 0 | BT13: 0 | BU13: 0
... A73: MEC LIII Superficial Trilayered Interneuron | B73: 0 | C73: 0 | D73: 0 | E73: 0 | F73: 0 | G73: 0 | H73: 0 | I73: 0 | J73: 0 | K73: 0 | L73: 0 | M73: 0 | N73: 0 | O73: 0 | P73: 0 | Q73: 0 | R73: 0 | S73: 0 | T73: 0 | U73: 0 | V73: 0 | W73: 0 | X73: 0 | Y73: 0 | Z73: 0 | AA73: 0 | AB73: 0 | AC73: 0 | AD73: 0 | AE73: 0 | AF73: 0 | AG73: 0 | AH73: 0 | AI73: 0 | AJ73: 0 | AK73: 0 | AL73: 0 | AM73: 0 | AN73: 0 | AO73: 0 | AP73: 0 | AQ73: 0 | AR73: 0 | AS73: 0 | AT73: 0 | AU73: 0 | AV73: 0 | AW73: 0 | AX73: 0 | AY73: 0 | AZ73: 0 | BA73: 0.01257 | BB73: 0.002671 | BC73: 0.01025 | BD73: 0.01015 | BE73: 0.01726 | BF73: 0.00302 | BG73: 0 | BH73: 0.002724 | BI73: 0 | BJ73: 0.008354 | BK73: 0.003995 | BL73: 0.002896 | BM73: 0.002988 | BN73: 0 | BO73: 0.002618 | BP73: 0 | BQ73: 0.01437 | BR73: 0.005589 | BS73: 0 | BT73: 0 | BU73: 0.01146

Sheet 72_gij
B1: DG Granule | C1: DG Semilunar Granule | D1: DG Mossy | E1: DG AIPRIM | F1: DG Axo Axonic | G1: DG Basket | H1: DG HICAP | I1: DG HIPP | J1: DG HIPROM | K1: DG MOLAX | L1: DG MOPP | M1: DG Neurogliaform | N1: DG Total Molecular Layer | O1: CA3 Pyramidal | P1: CA3c Pyramidal | Q1: CA3 Granule | R1: CA3 Axo Axonic | S1: CA3 Basket | T1: CA3 LMR Targeting | U1: CA3 Lucidum ORAX | V1: CA3 Spiny Lucidum | W1: CA3 Mossy Fiber Associated ORDEN | X1: CA3 Trilaminar | Y1: CA2 Basket | Z1: CA2 Wide Arbor Basket | AA1: CA2 Bistratified | AB1: CA2 SP SR | AC1: CA1 Pyramidal | AD1: CA1 Radiatum Giant | AE1: CA1 Axo Axonic | AF1: CA1 Horizontal Axo Axonic | AG1: CA1 Basket | AH1: CA1 Basket CCK+ | AI1: CA1 Horizontal Basket | AJ1: CA1 Ivy | AK1: CA1 LMR | AL1: CA1 Neurogliaform | AM1: CA1 Neurogliaform Projecting | AN1: CA1 Recurrent O LM | AO1: CA1 O LMR | AP1: CA1 Oriens Alveus | AQ1: CA1 Oriens Bistratified | AR1: CA1 OR LM | AS1: CA1 Perforant Path Associated | AT1: CA1 Perforant Path Associated QuadD | AU1: CA1 Radiatum | AV1: CA1 R Receiving Apical Targeting | AW1: CA1 Schaffer Collateral Associated | AX1: CA1 SO SO | AY1: CA1 Trilaminar | AZ1: CA1 Radial Trilaminar | BA1: EC LI II Multipolar Pyramidal | BB1: EC LI II Pyramidal Fan | BC1: MEC LII III Pyramidal Multiform | BD1: MEC LII Oblique Pyramidal | BE1: MEC LII Stellate | BF1: EC LII III Pyramidal Tripolar | BG1: LEC LIII Multipolar Principal | BH1: EC LIII Pyramidal | BI1: LEC LIII Complex Pyramidal | BJ1: MEC LIII Complex Pyramidal | BK1: MEC LIII Bipolar Complex Pyramidal | BL1: EC LIII Stellate | BM1: EC LIII V Bipolar Pyramidal | BN1: EC LIV VI Deep Multipolar Principal | BO1: EC LV Deep Pyramidal | BP1: MEC LV Multipolar Pyramidal | BQ1: MEC LV Pyramidal | BR1: MEC LV Superficial Pyramidal | BS1: MEC LV VI Pyramidal Polymorphic | BT1: LEC LVI Multipolar Pyramidal | BU1: MEC LIII Superficial Trilayered Interneuron
A2: DG Granule | D2: 1.49 | E2: 1.428 | F2: 1.403 | G2: 1.204 | H2: 1.105 | I2: 1.106 | J2: 1.488 | K2: 1.358 | N2: 1.376 | O2: 1.263 | P2: 1.815 | R2: 1.341 | S2: 1.498 | T2: 1.341 | U2: 1.328 | V2: 1.8870383 | W2: 1.359 | Y2: 2.05 | Z2: 1.252 | AA2: 1.453 | AB2: 1.191
A3: DG Semilunar Granule | B3: 1.4 | C3: 1.372 | D3: 1.534 | E3: 1.513 | F3: 1.491 | G3: 1.354 | H3: 1.188 | I3: 1.183 | J3: 1.595 | K3: 1.412 | N3: 1.442 | O3: 1.252 | P3: 1.88 | R3: 1.385 | S3: 1.582 | T3: 1.384 | U3: 1.382 | V3: 1.8938822 | W3: 1.425
A4: DG Mossy | B4: 1.993 | C4: 1.542 | D4: 1.76 | E4: 1.725 | F4: 1.812 | G4: 1.619 | H4: 1.223 | I4: 1.157 | J4: 1.857 | K4: 1.517 | N4: 1.639
A5: DG AIPRIM | B5: 2.379 | C5: 1.674 | D5: 1.734 | E5: 1.729 | F5: 1.725 | G5: 1.476 | H5: 1.181 | I5: 1.24 | J5: 1.868 | K5: 1.674 | N5: 1.782
A6: DG Axo Axonic | B6: 3.199 | D6: 2.378
A7: DG Basket | B7: 1.774 | F7: 1.386 | G7: 1.462 | H7: 1.032 | I7: 1.004 | K7: 1.277 | N7: 1.448
A8: DG HICAP | B8: 1 | C8: 0.8247 | E8: 0.8573 | F8: 0.8549 | G8: 0.8099 | H8: 0.4797 | J8: 0.9039 | K8: 0.8107 | N8: 0.8833
A9: DG HIPP | B9: 1.624 | C9: 1.414 | E9: 1.478 | F9: 1.506 | G9: 1.391 | H9: 1.049 | K9: 1.393 | L9: 1.431 | M9: 1.365 | N9: 1.522 | AM9: 1.533
A10: DG HIPROM | B10: 1.691 | C10: 1.467 | D10: 1.531 | E10: 1.497 | F10: 1.48 | G10: 1.333 | H10: 1.004 | I10: 1.078 | J10: 1.582 | K10: 1.432 | L10: 1.462 | M10: 1.393 | N10: 1.539 | O10: 1.267 | P10: 1.804 | Q10: 1.881 | R10: 1.537 | S10: 1.885 | T10: 1.461 | U10: 1.43 | V10: 2.3280498 | W10: 1.433 | X10: 1.477 | Z10: 1.324 | AM10: 1.503
A11: DG MOLAX | B11: 1.743 | C11: 1.327 | E11: 1.5 | F11: 1.371 | G11: 1.279 | H11: 1.035 | J11: 1.575 | K11: 1.134 | L11: 1.393 | M11: 1.332 | N11: 1.278 | AM11: 1.451
A12: DG MOPP | B12: 1.319 | C12: 1.08 | E12: 1.251 | F12: 1.194 | G12: 1.152 | H12: 0.8501 | K12: 1.082 | L12: 1.142 | M12: 1.086 | N12: 1.17 | AM12: 1.218
A13: DG Neurogliaform | B13: 1.431 | C13: 1.126 | E13: 1.309 | F13: 1.245 | G13: 1.192 | H13: 0.8794 | K13: 1.129 | L13: 1.199 | M13: 1.139 | N13: 1.229 | AM13: 1.26
A14: DG Total Molecular Layer | B14: 1.845 | C14: 1.487 | D14: 1.606 | E14: 1.605 | F14: 1.469 | G14: 1.333 | H14: 1.079 | I14: 1.155 | J14: 1.7 | K14: 1.275 | L14: 1.505 | M14: 1.433 | N14: 1.375 | AM14: 1.538
A15: CA3 Pyramidal | O15: 0.5531 | P15: 1.011 | Q15: 1.009 | R15: 0.9326 | S15: 1.172 | T15: 0.9208 | U15: 0.8518 | W15: 0.8803 | X15: 0.9432 | Y15: 1.228 | Z15: 0.8643 | AA15: 0.9381 | AB15: 0.819 | AC15: 0.9295 | AD15: 0.9459 | AE15: 0.8578 | AF15: 0.6662 | AG15: 0.8084 | AH15: 1.114 | AI15: 0.6887 | AJ15: 0.9431 | AK15: 0.83 | AN15: 0.717 | AO15: 0.6651 | AP15: 1.024 | AQ15: 1.014 | AR15: 0.8483 | AS15: 0.7615 | AT15: 0.8496 | AU15: 0.7737 | AV15: 0.8772 | AW15: 2.4843258 | AX15: 0.4782 | AY15: 0.9334 | AZ15: 0.651
A16: CA3c Pyramidal | B16: 1.798 | C16: 1.315 | D16: 1.642 | E16: 1.459 | F16: 1.454 | G16: 1.283 | H16: 1.064 | I16: 1.12 | J16: 1.523 | K16: 1.258 | N16: 1.366 | O16: 1.016 | P16: 1.426 | Q16: 1.484 | R16: 1.437 | S16: 1.708 | T16: 1.371 | U16: 1.33 | W16: 1.371 | X16: 1.459 | Y16: 1.886 | Z16: 1.276 | AA16: 1.433 | AB16: 1.196 | AC16: 1.285 | AD16: 1.445 | AE16: 1.282 | AF16: 1.02 | AG16: 1.236 | AH16: 1.641 | AI16: 1.053 | AJ16: 1.478 | AK16: 1.295 | AN16: 1.079 | AO16: 1.031 | AP16: 1.547 | AQ16: 1.558 | AR16: 1.335 | AS16: 1.181 | AT16: 1.33 | AU16: 1.214 | AV16: 1.353 | AX16: 0.7306 | AY16: 1.448 | AZ16: 0.9943
A17: CA3 Granule | O17: 1.165 | P17: 1.68 | R17: 1.514 | S17: 1.713 | T17: 1.525 | U17: 1.517 | V17: 1.6158274 | W17: 1.614
A18: CA3 Axo Axonic | O18: 1.87 | P18: 2.367
A19: CA3 Basket | O19: 1.572 | P19: 2.574 | R19: 2.025 | S19: 3.282 | W19: 1.809
A20: CA3 LMR Targeting | O20: 0.9955 | P20: 1.365 | Q20: 1.612 | R20: 1.315 | S20: 1.67 | T20: 1.273 | U20: 1.229 | W20: 1.222
A21: CA3 Lucidum ORAX | O21: 1.216 | P21: 1.731 | Q21: 1.811 | R21: 1.477 | S21: 1.825 | T21: 1.44 | U21: 1.39 | V21: 2.1960643 | W21: 1.396 | X21: 1.428 | Z21: 1.3
A22: CA3 Spiny Lucidum | B22: 2.6200608 | C22: 2.537386 | E22: 2.797598 | F22: 2.7386424 | G22: 3.0171896 | H22: 2.3150988 | J22: 2.941816 | K22: 2.7120035 | L22: 3.3976491 | M22: 2.5231185 | N22: 2.4632775 | O22: 2.565015 | P22: 2.6228158 | Q22: 2.2794772 | R22: 2.7161589 | S22: 2.6530307 | T22: 2.4313153 | U22: 2.5865215 | V22: 2.1082355 | W22: 2.5108647 | AM22: 2.5258076
A23: CA3 Mossy Fiber Associated ORDEN | D23: 1.682 | E23: 1.707 | F23: 1.599 | G23: 1.418 | H23: 1.167 | I23: 1.244 | J23: 1.769 | K23: 1.49 | N23: 1.613 | O23: 1.36 | P23: 1.857 | R23: 1.629 | S23: 1.972 | T23: 1.57 | U23: 1.537 | V23: 2.1021769 | W23: 1.553 | Z23: 1.406
A24: CA3 Trilaminar | O24: 1.142 | P24: 1.647 | Q24: 1.724 | R24: 1.388 | S24: 1.712 | T24: 1.365 | U24: 1.306 | V24: 2.3694797 | W24: 1.308 | X24: 1.36 | Z24: 1.23 | AC24: 1.364 | AD24: 1.44 | AE24: 1.346 | AF24: 1.03 | AG24: 1.258 | AH24: 1.543 | AI24: 1.061 | AJ24: 1.409 | AK24: 1.265 | AN24: 1.208 | AO24: 1.107 | AP24: 1.528 | AQ24: 1.605 | AR24: 1.333 | AS24: 1.144 | AT24: 1.324 | AU24: 1.185 | AV24: 1.391 | AW24: 2.6722392 | AX24: 0.7133 | AY24: 1.486 | AZ24: 0.9883
A25: CA2 Basket | Y25: 2.381 | Z25: 1.507 | AA25: 1.76 | AB25: 1.457
A26: CA2 Wide Arbor Basket | O26: 1.365 | P26: 1.972 | R26: 1.625 | S26: 1.973 | W26: 1.57 | Y26: 2.164 | Z26: 1.42 | AA26: 1.633 | AB26: 1.374 | AC26: 1.515 | AD26: 1.772 | AE26: 1.588 | AG26: 1.477 | AH26: 1.811 | AI26: 1.295 | AJ26: 1.66 | AR26: 1.597 | AZ26: 1.166
A27: CA2 Bistratified | Y27: 2.793 | Z27: 1.668 | AA27: 2.017 | AB27: 1.636 | AC27: 1.93 | AD27: 2.17 | AE27: 1.964 | AF27: 1.533 | AG27: 1.808 | AH27: 2.208 | AI27: 1.617 | AJ27: 1.994 | AK27: 1.884 | AN27: 1.769 | AO27: 1.623 | AP27: 2.261 | AQ27: 2.321 | AR27: 1.98 | AS27: 1.7 | AT27: 1.977 | AU27: 1.75 | AV27: 2.074 | AX27: 1.092 | AY27: 2.168 | AZ27: 1.383
A28: CA2 SP SR | Y28: 1.985 | Z28: 1.381 | AA28: 1.555 | AB28: 1.336
A29: CA1 Pyramidal | AC29: 1.272 | AE29: 1.433 | AF29: 1.263 | AG29: 1.299 | AH29: 1.925 | AI29: 1.046 | AJ29: 2.023 | AN29: 1.213 | AO29: 1.167 | AP29: 2.067 | AQ29: 1.671 | AR29: 1.437 | AT29: 1.458 | AX29: 0.6362 | AY29: 1.592 | AZ29: 1.03 | BG29: 1.39 | BM29: 1.332 | BN29: 1.383 | BO29: 1.392 | BP29: 1.396 | BQ29: 1.322 | BR29: 1.385 | BS29: 1.396 | BT29: 1.417
A30: CA1 Radiatum Giant | AC30: 1.205 | AE30: 1.204 | AF30: 0.9241 | AG30: 1.055 | AH30: 1.56 | AI30: 0.9697 | AJ30: 1.336 | AN30: 0.8791 | AO30: 0.8888 | AP30: 1.473 | AQ30: 1.39 | AR30: 1.171 | AT30: 1.182 | AX30: 0.677 | AY30: 1.314 | AZ30: 0.8699
A31: CA1 Axo Axonic | AC31: 2.353 | AD31: 2.7133343
A32: CA1 Horizontal Axo Axonic | AC32: 1.636 | AD32: 2.8651065
A33: CA1 Basket | AC33: 4.855 | AD33: 3.103 | AE33: 3.109 | AG33: 3.008 | AH33: 2.881 | AI33: 2.228 | AJ33: 2.886 | AR33: 2.899 | AZ33: 1.968
A34: CA1 Basket CCK+ | AC34: 1.502 | AD34: 1.429 | AE34: 1.254 | AG34: 1.19 | AH34: 1.418 | AI34: 0.9753 | AJ34: 1.431 | AR34: 1.329 | AZ34: 1.013
A35: CA1 Horizontal Basket | AC35: 1.159 | AD35: 1.291 | AE35: 1.278 | AG35: 1.206 | AH35: 1.433 | AI35: 1.013 | AJ35: 1.216 | AR35: 1.221 | AZ35: 0.8997
A36: CA1 Ivy | Z36: 1.193 | AC36: 1.194 | AD36: 1.368 | AE36: 1.295 | AF36: 0.9941 | AG36: 1.346 | AH36: 1.425 | AI36: 1.033 | AJ36: 1.374 | AK36: 1.217 | AN36: 1.15 | AO36: 1.078 | AP36: 1.417 | AQ36: 1.458 | AR36: 1.268 | AS36: 1.093 | AT36: 1.251 | AU36: 1.129 | AV36: 1.303 | AW36: 2.4628376 | AX36: 0.7178 | AY36: 1.359 | AZ36: 0.9803
A37: CA1 LMR | AC37: 1.456 | AD37: 1.608 | AE37: 1.522 | AG37: 1.487 | AH37: 1.697 | AJ37: 1.569 | AK37: 1.398 | AL37: 1.721 | AM37: 1.643 | AP37: 1.664 | AR37: 1.496 | AS37: 1.28 | AT37: 1.491 | AU37: 1.302 | AV37: 1.546 | AW37: 2.2665958 | AZ37: 1.109
A38: CA1 Neurogliaform | AC38: 1.209 | AD38: 1.279 | AE38: 1.214 | AG38: 1.18 | AH38: 1.397 | AK38: 1.067 | AL38: 1.344 | AM38: 1.284 | AP38: 1.346 | AS38: 0.9966 | AT38: 1.17 | AW38: 2.4276404 | AZ38: 0.8575
A39: CA1 Neurogliaform Projecting | B39: 1.485 | C39: 1.12 | E39: 1.285 | F39: 1.24 | G39: 1.147 | H39: 0.9055 | K39: 1.154 | L39: 1.192 | M39: 1.132 | N39: 1.23 | AC39: 1.242 | AD39: 1.279 | AE39: 1.22 | AG39: 1.192 | AH39: 1.394 | AK39: 1.065 | AL39: 1.34 | AM39: 1.276 | AP39: 1.358 | AS39: 1.002 | AT39: 1.178 | AW39: 2.4721482 | AZ39: 0.8668
A40: CA1 Recurrent O LM | AC40: 1.524 | AD40: 1.586 | AE40: 1.488 | AF40: 1.14 | AG40: 1.419 | AH40: 1.689 | AI40: 1.189 | AJ40: 1.519 | AK40: 1.353 | AL40: 1.537 | AM40: 1.467 | AN40: 1.327 | AO40: 1.252 | AP40: 1.662 | AQ40: 1.7 | AR40: 1.475 | AS40: 1.258 | AT40: 1.463 | AW40: 2.4698769 | AX40: 0.8227 | AY40: 1.597 | AZ40: 1.066
...

Sheet 72_taudij
B1: DG Granule | C1: DG Semilunar Granule | D1: DG Mossy | E1: DG AIPRIM | F1: DG Axo Axonic | G1: DG Basket | H1: DG HICAP | I1: DG HIPP | J1: DG HIPROM | K1: DG MOLAX | L1: DG MOPP | M1: DG Neurogliaform | N1: DG Total Molecular Layer | O1: CA3 Pyramidal | P1: CA3c Pyramidal | Q1: CA3 Granule | R1: CA3 Axo Axonic | S1: CA3 Basket | T1: CA3 LMR Targeting | U1: CA3 Lucidum ORAX | V1: CA3 Spiny Lucidum | W1: CA3 Mossy Fiber Associated ORDEN | X1: CA3 Trilaminar | Y1: CA2 Basket | Z1: CA2 Wide Arbor Basket | AA1: CA2 Bistratified | AB1: CA2 SP SR | AC1: CA1 Pyramidal | AD1: CA1 Radiatum Giant | AE1: CA1 Axo Axonic | AF1: CA1 Horizontal Axo Axonic | AG1: CA1 Basket | AH1: CA1 Basket CCK+ | AI1: CA1 Horizontal Basket | AJ1: CA1 Ivy | AK1: CA1 LMR | AL1: CA1 Neurogliaform | AM1: CA1 Neurogliaform Projecting | AN1: CA1 Recurrent O LM | AO1: CA1 O LMR | AP1: CA1 Oriens Alveus | AQ1: CA1 Oriens Bistratified | AR1: CA1 OR LM | AS1: CA1 Perforant Path Associated | AT1: CA1 Perforant Path Associated QuadD | AU1: CA1 Radiatum | AV1: CA1 R Receiving Apical Targeting | AW1: CA1 Schaffer Collateral Associated | AX1: CA1 SO SO | AY1: CA1 Trilaminar | AZ1: CA1 Radial Trilaminar | BA1: EC LI II Multipolar Pyramidal | BB1: EC LI II Pyramidal Fan | BC1: MEC LII III Pyramidal Multiform | BD1: MEC LII Oblique Pyramidal | BE1: MEC LII Stellate | BF1: EC LII III Pyramidal Tripolar | BG1: LEC LIII Multipolar Principal | BH1: EC LIII Pyramidal | BI1: LEC LIII Complex Pyramidal | BJ1: MEC LIII Complex Pyramidal | BK1: MEC LIII Bipolar Complex Pyramidal | BL1: EC LIII Stellate | BM1: EC LIII V Bipolar Pyramidal | BN1: EC LIV VI Deep Multipolar Principal | BO1: EC LV Deep Pyramidal | BP1: MEC LV Multipolar Pyramidal | BQ1: MEC LV Pyramidal | BR1: MEC LV Superficial Pyramidal | BS1: MEC LV VI Pyramidal Polymorphic | BT1: LEC LVI Multipolar Pyramidal | BU1: MEC LIII Superficial Trilayered Interneuron
A2: DG Granule | D2: 5.468 | E2: 4.665 | F2: 5.033 | G2: 3.743 | H2: 4.756 | I2: 5.31 | J2: 4.92 | K2: 4.929 | N2: 4.814 | O2: 7.426 | P2: 7.046 | R2: 4.127 | S2: 3.583 | T2: 4.925 | U2: 4.969 | V2: 8.0653349 | W2: 4.867 | Y2: 4.106 | Z2: 4.72 | AA2: 4.012 | AB2: 3.386
A3: DG Semilunar Granule | B3: 6.305 | C3: 5.055 | D3: 4.795 | E3: 4.661 | F3: 4.678 | G3: 4.225 | H3: 4.809 | I3: 5.259 | J3: 4.935 | K3: 4.972 | N3: 4.901 | O3: 7.897 | P3: 7.143 | R3: 4.11 | S3: 3.496 | T3: 4.972 | U3: 5.029 | V3: 8.4849409 | W3: 4.882
A4: DG Mossy | B4: 5.831 | C4: 4.624 | D4: 4.337 | E4: 3.969 | F4: 3.988 | G4: 3.618 | H4: 4.382 | I4: 4.953 | J4: 4.282 | K4: 4.668 | N4: 4.497
A5: DG AIPRIM | B5: 7.215 | C5: 6.049 | D5: 5.803 | E5: 5.947 | F5: 5.816 | G5: 5.617 | H5: 6.239 | I5: 7.029 | J5: 6.32 | K5: 6.093 | N5: 5.934
A6: DG Axo Axonic | B6: 4.406 | D6: 4.081
A7: DG Basket | B7: 6.846 | F7: 5.492 | G7: 4.56 | H7: 5.934 | I7: 6.458 | K7: 5.992 | N7: 5.736
A8: DG HICAP | B8: 10.17 | C8: 7.02 | E8: 6.993 | F8: 6.887 | G8: 6.465 | H8: 7.177 | J8: 7.274 | K8: 7.079 | N8: 6.875
A9: DG HIPP | B9: 9.22 | C9: 6.696 | E9: 6.54 | F9: 6.655 | G9: 6.005 | H9: 6.74 | K9: 6.756 | L9: 6.756 | M9: 6.802 | N9: 6.506 | AM9: 6.981
A10: DG HIPROM | B10: 8.093 | C10: 6.228 | D10: 5.929 | E10: 6.302 | F10: 6.005 | G10: 5.502 | H10: 6.496 | I10: 7.281 | J10: 6.591 | K10: 6.345 | L10: 6.325 | M10: 6.367 | N10: 6.189 | O10: 8.883 | P10: 8.039 | Q10: 6.525 | R10: 5.203 | S10: 4.333 | T10: 6.209 | U10: 6.471 | V10: 8.9028179 | W10: 6.43 | X10: 6.36 | Z10: 5.915 | AM10: 6.612
A11: DG MOLAX | B11: 7.531 | C11: 6.123 | E11: 5.613 | F11: 5.796 | G11: 5.352 | H11: 5.947 | J11: 5.932 | K11: 6.173 | L11: 5.979 | M11: 6.003 | N11: 5.906 | AM11: 6.21
A12: DG MOPP | B12: 9.88 | C12: 7.3 | E12: 6.567 | F12: 6.767 | G12: 6.162 | H12: 6.864 | K12: 7.115 | L12: 7.092 | M12: 7.145 | N12: 6.923 | AM12: 7.345
A13: DG Neurogliaform | B13: 9.295 | C13: 7.09 | E13: 6.356 | F13: 6.556 | G13: 5.986 | H13: 6.679 | K13: 6.896 | L13: 6.854 | M13: 6.916 | N13: 6.706 | AM13: 7.149
A14: DG Total Molecular Layer | B14: 7.041 | C14: 5.585 | D14: 5.296 | E14: 5.285 | F14: 5.433 | G14: 5.031 | H14: 5.681 | I14: 6.153 | J14: 5.581 | K14: 5.694 | L14: 5.596 | M14: 5.631 | N14: 5.537 | AM14: 5.861
A15: CA3 Pyramidal | O15: 10.22 | P15: 7.961 | Q15: 5.877 | R15: 4.923 | S15: 3.971 | T15: 5.667 | U15: 6.046 | W15: 5.948 | X15: 5.592 | Y15: 5.05 | Z15: 5.555 | AA15: 5.054 | AB15: 4.52 | AC15: 6.675 | AD15: 6.228 | AE15: 5.305 | AF15: 6.628 | AG15: 5.018 | AH15: 4.589 | AI15: 5.624 | AJ15: 6.238 | AK15: 5.805 | AN15: 5.708 | AO15: 6.327 | AP15: 5.306 | AQ15: 5.509 | AR15: 6.049 | AS15: 6.029 | AT15: 6.022 | AU15: 6.143 | AV15: 5.868 | AW15: 7.570896 | AX15: 7.74 | AY15: 5.632 | AZ15: 6.677
A16: CA3c Pyramidal | B16: 6.2 | C16: 4.829 | D16: 4.231 | E16: 4.383 | F16: 4.314 | G16: 4.086 | H16: 4.697 | I16: 5.071 | J16: 4.651 | K16: 4.812 | N16: 4.671 | O16: 8.097 | P16: 7.005 | Q16: 4.959 | R16: 3.92 | S16: 3.296 | T16: 4.661 | U16: 4.843 | W16: 4.777 | X16: 4.492 | Y16: 3.995 | Z16: 4.593 | AA16: 4.029 | AB16: 3.72 | AC16: 5.698 | AD16: 5.025 | AE16: 4.313 | AF16: 5.349 | AG16: 4.041 | AH16: 3.713 | AI16: 4.522 | AJ16: 5.101 | AK16: 4.602 | AN16: 4.694 | AO16: 5.133 | AP16: 4.32 | AQ16: 4.496 | AR16: 4.84 | AS16: 4.844 | AT16: 4.852 | AU16: 4.895 | AV16: 4.697 | AX16: 6.387 | AY16: 4.526 | AZ16: 5.42
A17: CA3 Granule | O17: 6.999 | P17: 6.204 | R17: 3.071 | S17: 2.677 | T17: 3.777 | U17: 3.752 | V17: 8.4036142 | W17: 3.632
A18: CA3 Axo Axonic | O18: 7.623 | P18: 7.206
A19: CA3 Basket | O19: 7.639 | P19: 6.85 | R19: 3.8 | S19: 3.007 | W19: 5.231
A20: CA3 LMR Targeting | O20: 9.563 | P20: 8.788 | Q20: 6.696 | R20: 5.369 | S20: 4.448 | T20: 6.402 | U20: 6.684 | W20: 6.627
A21: CA3 Lucidum ORAX | O21: 8.461 | P21: 7.656 | Q21: 6.183 | R21: 5.002 | S21: 4.184 | T21: 5.909 | U21: 6.185 | V21: 9.7157517 | W21: 6.119 | X21: 6.058 | Z21: 5.648
A22: CA3 Spiny Lucidum | B22: 10.984341 | C22: 8.7908863 | E22: 8.3937515 | F22: 7.5565306 | G22: 7.9134771 | H22: 8.5814268 | J22: 9.2441102 | K22: 7.9264258 | L22: 8.7685607 | M22: 8.1858823 | N22: 8.3584842 | O22: 9.3460933 | P22: 8.1177789 | Q22: 8.2250083 | R22: 7.7336087 | S22: 7.8282669 | T22: 8.4226492 | U22: 8.2505779 | V22: 8.8043244 | W22: 8.823998 | AM22: 9.0657887
A23: CA3 Mossy Fiber Associated ORDEN | D23: 5.127 | E23: 5.193 | F23: 5.215 | G23: 4.969 | H23: 5.451 | I23: 6.129 | J23: 5.522 | K23: 5.537 | N23: 5.357 | O23: 7.149 | P23: 6.469 | R23: 4.55 | S23: 3.896 | T23: 5.387 | U23: 5.58 | V23: 8.7839499 | W23: 5.534 | Z23: 5.17
A24: CA3 Trilaminar | O24: 8.711 | P24: 7.864 | Q24: 6.298 | R24: 5.148 | S24: 4.298 | T24: 6.048 | U24: 6.345 | V24: 9.5743175 | W24: 6.272 | X24: 6.162 | Z24: 5.776 | AC24: 6.902 | AD24: 6.589 | AE24: 5.453 | AF24: 7.054 | AG24: 5.222 | AH24: 5.049 | AI24: 6.068 | AJ24: 6.906 | AK24: 6.085 | AN24: 5.797 | AO24: 6.425 | AP24: 5.689 | AQ24: 5.697 | AR24: 6.336 | AS24: 6.432 | AT24: 6.333 | AU24: 6.325 | AV24: 5.968 | AW24: 8.6549181 | AX24: 8.164 | AY24: 5.691 | AZ24: 7.592
A25: CA2 Basket | Y25: 5.061 | Z25: 5.504 | AA25: 5.186 | AB25: 4.402
A26: CA2 Wide Arbor Basket | O26: 9.796 | P26: 8.737 | R26: 5.787 | S26: 4.803 | W26: 7.044 | Y26: 6.04 | Z26: 6.373 | AA26: 6.145 | AB26: 5.203 | AC26: 7.583 | AD26: 7.533 | AE26: 6.124 | AG26: 5.806 | AH26: 5.623 | AI26: 6.726 | AJ26: 7.79 | AR26: 7.113 | AZ26: 8.671
A27: CA2 Bistratified | Y27: 4.552 | Z27: 5.079 | AA27: 4.682 | AB27: 4.004 | AC27: 6.145 | AD27: 5.793 | AE27: 4.692 | AF27: 6.109 | AG27: 4.48 | AH27: 4.37 | AI27: 5.193 | AJ27: 5.922 | AK27: 5.249 | AN27: 5.011 | AO27: 5.534 | AP27: 4.867 | AQ27: 4.93 | AR27: 5.474 | AS27: 5.556 | AT27: 5.429 | AU27: 5.441 | AV27: 5.139 | AX27: 6.98 | AY27: 4.893 | AZ27: 6.686
A28: CA2 SP SR | Y28: 5.248 | Z28: 5.538 | AA28: 5.248 | AB28: 4.48
A29: CA1 Pyramidal | AC29: 5.978 | AE29: 3.158 | AF29: 3.933 | AG29: 2.984 | AH29: 2.643 | AI29: 3.656 | AJ29: 3.673 | AN29: 3.592 | AO29: 4.045 | AP29: 3.2 | AQ29: 3.713 | AR29: 3.94 | AT29: 3.897 | AX29: 6.225 | AY29: 3.774 | AZ29: 4.331 | BG29: 3.902 | BM29: 4.055 | BN29: 3.722 | BO29: 3.709 | BP29: 3.786 | BQ29: 3.957 | BR29: 3.814 | BS29: 3.719 | BT29: 3.856
A30: CA1 Radiatum Giant | AC30: 5.787 | AE30: 4.116 | AF30: 5.073 | AG30: 3.991 | AH30: 3.462 | AI30: 4.237 | AJ30: 4.73 | AN30: 4.696 | AO30: 4.971 | AP30: 3.813 | AQ30: 4.288 | AR30: 4.652 | AT30: 4.605 | AX30: 6.151 | AY30: 4.364 | AZ30: 5.026
A31: CA1 Axo Axonic | AC31: 5.649 | AD31: 8.7678444
A32: CA1 Horizontal Axo Axonic | AC32: 6.278 | AD32: 8.5466525
A33: CA1 Basket | AC33: 3.972 | AD33: 4.62 | AE33: 3.641 | AG33: 3.381 | AH33: 3.787 | AI33: 4.449 | AJ33: 4.631 | AR33: 4.391 | AZ33: 5.311
A34: CA1 Basket CCK+ | AC34: 7.144 | AD34: 7.131 | AE34: 6.499 | AG34: 5.828 | AH34: 5.598 | AI34: 7.104 | AJ34: 7.332 | AR34: 6.812 | AZ34: 8.272
A35: CA1 Horizontal Basket | AC35: 7.547 | AD35: 8.406 | AE35: 6.602 | AG35: 6.216 | AH35: 6.211 | AI35: 7.353 | AJ35: 11.43 | AR35: 7.846 | AZ35: 12.69
A36: CA1 Ivy | Z36: 6.837 | AC36: 8.687 | AD36: 8.338 | AE36: 6.383 | AF36: 8.523 | AG36: 5.724 | AH36: 6.243 | AI36: 7.342 | AJ36: 8.555 | AK36: 7.246 | AN36: 6.888 | AO36: 7.674 | AP36: 6.812 | AQ36: 6.905 | AR36: 7.907 | AS36: 7.704 | AT36: 7.694 | AU36: 7.639 | AV36: 7.158 | AW36: 9.0615371 | AX36: 9.522 | AY36: 6.839 | AZ36: 9.602
A37: CA1 LMR | AC37: 7.189 | AD37: 6.675 | AE37: 5.359 | AG37: 5.039 | AH37: 4.996 | AJ37: 6.907 | AK37: 6.031 | AL37: 6.406 | AM37: 6.403 | AP37: 5.672 | AR37: 6.399 | AS37: 6.375 | AT37: 6.303 | AU37: 6.344 | AV37: 5.989 | AW37: 9.0849073 | AZ37: 7.549
A38: CA1 Neurogliaform | AC38: 7.803 | AD38: 7.678 | AE38: 6.23 | AG38: 5.831 | AH38: 5.682 | AK38: 7.22 | AL38: 8.163 | AM38: 8.12 | AP38: 6.487 | AS38: 7.321 | AT38: 7.359 | AW38: 11.176847 | AZ38: 8.942
A39: CA1 Neurogliaform Projecting | B39: 8.472 | C39: 7.357 | E39: 6.64 | F39: 6.761 | G39: 6.242 | H39: 6.871 | K39: 7.112 | L39: 7.095 | M39: 7.157 | N39: 6.936 | AC39: 7.806 | AD39: 7.682 | AE39: 6.253 | AG39: 5.828 | AH39: 5.703 | AK39: 7.251 | AL39: 8.148 | AM39: 8.158 | AP39: 6.455 | AS39: 7.352 | AT39: 7.347 | AW39: 10.540688 | AZ39: 8.837
A40: CA1 Recurrent O LM | AC40: 6.82 | AD40: 6.463 | AE40: 5.34 | AF40: 6.852 | AG40: 5.001 | AH40: 4.922 | AI40: 5.857 | AJ40: 6.777 | AK40: 6.029 | AL40: 6.26 | AM40: 6.261 | AN40: 5.559 | AO40: 6.162 | AP40: 5.53 | AQ40: 5.575 | AR40: 6.168 | AS40: 6.284 | AT40: 6.164 | AW40: 8.8191704 | AX40: 7.857 | AY40: 5.508 | AZ40: 7.409
...

Sheet 72_vij
B1: DG Granule | C1: DG Semilunar Granule | D1: DG Mossy | E1: DG AIPRIM | F1: DG Axo Axonic | G1: DG Basket | H1: DG HICAP | I1: DG HIPP | J1: DG HIPROM | K1: DG MOLAX | L1: DG MOPP | M1: DG Neurogliaform | N1: DG Total Molecular Layer | O1: CA3 Pyramidal | P1: CA3c Pyramidal | Q1: CA3 Granule | R1: CA3 Axo Axonic | S1: CA3 Basket | T1: CA3 LMR Targeting | U1: CA3 Lucidum ORAX | V1: CA3 Spiny Lucidum | W1: CA3 Mossy Fiber Associated ORDEN | X1: CA3 Trilaminar | Y1: CA2 Basket | Z1: CA2 Wide Arbor Basket | AA1: CA2 Bistratified | AB1: CA2 SP SR | AC1: CA1 Pyramidal | AD1: CA1 Radiatum Giant | AE1: CA1 Axo Axonic | AF1: CA1 Horizontal Axo Axonic | AG1: CA1 Basket | AH1: CA1 Basket CCK+ | AI1: CA1 Horizontal Basket | AJ1: CA1 Ivy | AK1: CA1 LMR | AL1: CA1 Neurogliaform | AM1: CA1 Neurogliaform Projecting | AN1: CA1 Recurrent O LM | AO1: CA1 O LMR | AP1: CA1 Oriens Alveus | AQ1: CA1 Oriens Bistratified | AR1: CA1 OR LM | AS1: CA1 Perforant Path Associated | AT1: CA1 Perforant Path Associated QuadD | AU1: CA1 Radiatum | AV1: CA1 R Receiving Apical Targeting | AW1: CA1 Schaffer Collateral Associated | AX1: CA1 SO SO | AY1: CA1 Trilaminar | AZ1: CA1 Radial Trilaminar | BA1: EC LI II Multipolar Pyramidal | BB1: EC LI II Pyramidal Fan | BC1: MEC LII III Pyramidal Multiform | BD1: MEC LII Oblique Pyramidal | BE1: MEC LII Stellate | BF1: EC LII III Pyramidal Tripolar | BG1: LEC LIII Multipolar Principal | BH1: EC LIII Pyramidal | BI1: LEC LIII Complex Pyramidal | BJ1: MEC LIII Complex Pyramidal | BK1: MEC LIII Bipolar Complex Pyramidal | BL1: EC LIII Stellate | BM1: EC LIII V Bipolar Pyramidal | BN1: EC LIV VI Deep Multipolar Principal | BO1: EC LV Deep Pyramidal | BP1: MEC LV Multipolar Pyramidal | BQ1: MEC LV Pyramidal | BR1: MEC LV Superficial Pyramidal | BS1: MEC LV VI Pyramidal Polymorphic | BT1: LEC LVI Multipolar Pyramidal | BU1: MEC LIII Superficial Trilayered Interneuron
A2: DG Granule | B2: 75 | C2: 78 | D2: 62 | E2: 64 | F2: 65.1 | G2: 62 | H2: 60.5 | I2: 60 | J2: 65 | K2: 54.5 | L2: 75.6 | M2: 75.6 | N2: 54.5 | O2: 60.5 | P2: 62 | Q2: 78 | R2: 58 | S2: 74.9 | T2: 68 | U2: 61 | V2: 60 | W2: 57 | X2: 61.2 | Y2: 71.2 | Z2: 74.9 | AA2: 72.7 | AB2: 71 | AC2: 62.4 | AD2: 66 | AE2: 65.1 | AF2: 57 | AG2: 57 | AH2: 61.4 | AI2: 55.4 | AJ2: 71 | AK2: 53.1 | AL2: 63.1 | AM2: 63.1 | AN2: 75 | AO2: 55.7 | AP2: 51 | AQ2: 66 | AR2: 68 | AS2: 55.4 | AT2: 64 | AU2: 55.8 | AV2: 57 | AW2: 60.6 | AX2: 59 | AY2: 64 | AZ2: 57 | BA2: 63 | BB2: 56.5 | BC2: 63 | BD2: 60.5 | BE2: 60.5 | BF2: 60.5 | BG2: 66.5 | BH2: 66.5 | BI2: 66.5 | BJ2: 61 | BK2: 61 | BL2: 61 | BM2: 68 | BN2: 59.8 | BO2: 66.5 | BP2: 66.5 | BQ2: 61.8 | BR2: 66.5 | BS2: 63 | BT2: 64 | BU2: 62
A3: DG Semilunar Granule | B3: 75 | C3: 78 | D3: 62 | E3: 64 | F3: 65.1 | G3: 62 | H3: 60.5 | I3: 60 | J3: 65 | K3: 54.5 | L3: 75.6 | M3: 75.6 | N3: 54.5 | O3: 60.5 | P3: 62 | Q3: 78 | R3: 58 | S3: 74.9 | T3: 68 | U3: 61 | V3: 60 | W3: 57 | X3: 61.2 | Y3: 71.2 | Z3: 74.9 | AA3: 72.7 | AB3: 71 | AC3: 62.4 | AD3: 66 | AE3: 65.1 | AF3: 57 | AG3: 57 | AH3: 61.4 | AI3: 55.4 | AJ3: 71 | AK3: 53.1 | AL3: 63.1 | AM3: 63.1 | AN3: 75 | AO3: 55.7 | AP3: 51 | AQ3: 66 | AR3: 68 | AS3: 55.4 | AT3: 64 | AU3: 55.8 | AV3: 57 | AW3: 60.6 | AX3: 59 | AY3: 64 | AZ3: 57 | BA3: 63 | BB3: 56.5 | BC3: 63 | BD3: 60.5 | BE3: 60.5 | BF3: 60.5 | BG3: 66.5 | BH3: 66.5 | BI3: 66.5 | BJ3: 61 | BK3: 61 | BL3: 61 | BM3: 68 | BN3: 59.8 | BO3: 66.5 | BP3: 66.5 | BQ3: 61.8 | BR3: 66.5 | BS3: 63 | BT3: 64 | BU3: 62
A4: DG Mossy | B4: 75 | C4: 78 | D4: 62 | E4: 64 | F4: 65.1 | G4: 62 | H4: 60.5 | I4: 60 | J4: 65 | K4: 54.5 | L4: 75.6 | M4: 75.6 | N4: 54.5 | O4: 60.5 | P4: 62 | Q4: 78 | R4: 58 | S4: 74.9 | T4: 68 | U4: 61 | V4: 60 | W4: 57 | X4: 61.2 | Y4: 71.2 | Z4: 74.9 | AA4: 72.7 | AB4: 71 | AC4: 62.4 | AD4: 66 | AE4: 65.1 | AF4: 57 | AG4: 57 | AH4: 61.4 | AI4: 55.4 | AJ4: 71 | AK4: 53.1 | AL4: 63.1 | AM4: 63.1 | AN4: 75 | AO4: 55.7 | AP4: 51 | AQ4: 66 | AR4: 68 | AS4: 55.4 | AT4: 64 | AU4: 55.8 | AV4: 57 | AW4: 60.6 | AX4: 59 | AY4: 64 | AZ4: 57 | BA4: 63 | BB4: 56.5 | BC4: 63 | BD4: 60.5 | BE4: 60.5 | BF4: 60.5 | BG4: 66.5 | BH4: 66.5 | BI4: 66.5 | BJ4: 61 | BK4: 61 | BL4: 61 | BM4: 68 | BN4: 59.8 | BO4: 66.5 | BP4: 66.5 | BQ4: 61.8 | BR4: 66.5 | BS4: 63 | BT4: 64 | BU4: 62
A5: DG AIPRIM | B5: -20.6 | C5: -29 | D5: -31.7 | E5: -22 | F5: -17.9 | G5: -26.3 | H5: -29 | I5: -29 | J5: -31.2 | K5: -30.7 | L5: -40 | M5: -40 | N5: -30.7 | O5: -37.5 | P5: -23 | Q5: -19.4 | R5: -22.5 | S5: -20.7 | T5: -24 | U5: -28.2 | V5: -34.8 | W5: -33 | X5: -20.8 | Y5: -20.8 | Z5: -25.1 | AA5: -46.3 | AB5: -18 | AC5: -27.8 | AD5: -34 | AE5: -26.9 | AF5: -38 | AG5: -32 | AH5: -31.1 | AI5: -38.6 | AJ5: -29.1 | AK5: -53.8 | AL5: -39.3 | AM5: -51.3 | AN5: -20 | AO5: -48.3 | AP5: -28.4 | AQ5: -30 | AR5: -17.1 | AS5: -23.9 | AT5: -33 | AU5: -33.6 | AV5: -38 | AW5: -22.9 | AX5: -35 | AY5: -33 | AZ5: -40 | BA5: -22.6 | BB5: -31.3 | BC5: -22.6 | BD5: -17.5 | BE5: -17.5 | BF5: -17.5 | BG5: -27.1 | BH5: -27.1 | BI5: -27.1 | BJ5: -28.5 | BK5: -26.2 | BL5: -28.5 | BM5: -22 | BN5: -24.7 | BO5: -32.2 | BP5: -32.2 | BQ5: -18.2 | BR5: -32.2 | BS5: -34.7 | BT5: -33.9 | BU5: -16
A6: DG Axo Axonic | B6: -20.6 | C6: -29 | D6: -31.7 | E6: -22 | F6: -17.9 | G6: -26.3 | H6: -29 | I6: -29 | J6: -31.2 | K6: -30.7 | L6: -40 | M6: -40 | N6: -30.7 | O6: -37.5 | P6: -23 | Q6: -19.4 | R6: -22.5 | S6: -20.7 | T6: -24 | U6: -28.2 | V6: -34.8 | W6: -33 | X6: -20.8 | Y6: -20.8 | Z6: -25.1 | AA6: -46.3 | AB6: -18 | AC6: -27.8 | AD6: -34 | AE6: -26.9 | AF6: -38 | AG6: -32 | AH6: -31.1 | AI6: -38.6 | AJ6: -29.1 | AK6: -53.8 | AL6: -39.3 | AM6: -51.3 | AN6: -20 | AO6: -48.3 | AP6: -28.4 | AQ6: -30 | AR6: -17.1 | AS6: -23.9 | AT6: -33 | AU6: -33.6 | AV6: -38 | AW6: -22.9 | AX6: -35 | AY6: -33 | AZ6: -40 | BA6: -22.6 | BB6: -31.3 | BC6: -22.6 | BD6: -17.5 | BE6: -17.5 | BF6: -17.5 | BG6: -27.1 | BH6: -27.1 | BI6: -27.1 | BJ6: -28.5 | BK6: -26.2 | BL6: -28.5 | BM6: -22 | BN6: -24.7 | BO6: -32.2 | BP6: -32.2 | BQ6: -18.2 | BR6: -32.2 | BS6: -34.7 | BT6: -33.9 | BU6: -16
A7: DG Basket | B7: -20.6 | C7: -29 | D7: -31.7 | E7: -22 | F7: -17.9 | G7: -26.3 | H7: -29 | I7: -29 | J7: -31.2 | K7: -30.7 | L7: -40 | M7: -40 | N7: -30.7 | O7: -37.5 | P7: -23 | Q7: -19.4 | R7: -22.5 | S7: -20.7 | T7: -24 | U7: -28.2 | V7: -34.8 | W7: -33 | X7: -20.8 | Y7: -20.8 | Z7: -25.1 | AA7: -46.3 | AB7: -18 | AC7: -27.8 | AD7: -34 | AE7: -26.9 | AF7: -38 | AG7: -32 | AH7: -31.1 | AI7: -38.6 | AJ7: -29.1 | AK7: -53.8 | AL7: -39.3 | AM7: -51.3 | AN7: -20 | AO7: -48.3 | AP7: -28.4 | AQ7: -30 | AR7: -17.1 | AS7: -23.9 | AT7: -33 | AU7: -33.6 | AV7: -38 | AW7: -22.9 | AX7: -35 | AY7: -33 | AZ7: -40 | BA7: -22.6 | BB7: -31.3 | BC7: -22.6 | BD7: -17.5 | BE7: -17.5 | BF7: -17.5 | BG7: -27.1 | BH7: -27.1 | BI7: -27.1 | BJ7: -28.5 | BK7: -26.2 | BL7: -28.5 | BM7: -22 | BN7: -24.7 | BO7: -32.2 | BP7: -32.2 | BQ7: -18.2 | BR7: -32.2 | BS7: -34.7 | BT7: -33.9 | BU7: -16
A8: DG HICAP | B8: -20.6 | C8: -29 | D8: -31.7 | E8: -22 | F8: -17.9 | G8: -26.3 | H8: -29 | I8: -29 | J8: -31.2 | K8: -30.7 | L8: -40 | M8: -40 | N8: -30.7 | O8: -37.5 | P8: -23 | Q8: -19.4 | R8: -22.5 | S8: -20.7 | T8: -24 | U8: -28.2 | V8: -34.8 | W8: -33 | X8: -20.8 | Y8: -20.8 | Z8: -25.1 | AA8: -46.3 | AB8: -18 | AC8: -27.8 | AD8: -34 | AE8: -26.9 | AF8: -38 | AG8: -32 | AH8: -31.1 | AI8: -38.6 | AJ8: -29.1 | AK8: -53.8 | AL8: -39.3 | AM8: -51.3 | AN8: -20 | AO8: -48.3 | AP8: -28.4 | AQ8: -30 | AR8: -17.1 | AS8: -23.9 | AT8: -33 | AU8: -33.6 | AV8: -38 | AW8: -22.9 | AX8: -35 | AY8: -33 | AZ8: -40 | BA8: -22.6 | BB8: -31.3 | BC8: -22.6 | BD8: -17.5 | BE8: -17.5 | BF8: -17.5 | BG8: -27.1 | BH8: -27.1 | BI8: -27.1 | BJ8: -28.5 | BK8: -26.2 | BL8: -28.5 | BM8: -22 | BN8: -24.7 | BO8: -32.2 | BP8: -32.2 | BQ8: -18.2 | BR8: -32.2 | BS8: -34.7 | BT8: -33.9 | BU8: -16
A9: DG HIPP | B9: -20.6 | C9: -29 | D9: -31.7 | E9: -22 | F9: -17.9 | G9: -26.3 | H9: -29 | I9: -29 | J9: -31.2 | K9: -30.7 | L9: -40 | M9: -40 | N9: -30.7 | O9: -37.5 | P9: -23 | Q9: -19.4 | R9: -22.5 | S9: -20.7 | T9: -24 | U9: -28.2 | V9: -34.8 | W9: -33 | X9: -20.8 | Y9: -20.8 | Z9: -25.1 | AA9: -46.3 | AB9: -18 | AC9: -27.8 | AD9: -34 | AE9: -26.9 | AF9: -38 | AG9: -32 | AH9: -31.1 | AI9: -38.6 | AJ9: -29.1 | AK9: -53.8 | AL9: -39.3 | AM9: -51.3 | AN9: -20 | AO9: -48.3 | AP9: -28.4 | AQ9: -30 | AR9: -17.1 | AS9: -23.9 | AT9: -33 | AU9: -33.6 | AV9: -38 | AW9: -22.9 | AX9: -35 | AY9: -33 | AZ9: -40 | BA9: -22.6 | BB9: -31.3 | BC9: -22.6 | BD9: -17.5 | BE9: -17.5 | BF9: -17.5 | BG9: -27.1 | BH9: -27.1 | BI9: -27.1 | BJ9: -28.5 | BK9: -26.2 | BL9: -28.5 | BM9: -22 | BN9: -24.7 | BO9: -32.2 | BP9: -32.2 | BQ9: -18.2 | BR9: -32.2 | BS9: -34.7 | BT9: -33.9 | BU9: -16
A10: DG HIPROM | B10: -20.6 | C10: -29 | D10: -31.7 | E10: -22 | F10: -17.9 | G10: -26.3 | H10: -29 | I10: -29 | J10: -31.2 | K10: -30.7 | L10: -40 | M10: -40 | N10: -30.7 | O10: -37.5 | P10: -23 | Q10: -19.4 | R10: -22.5 | S10: -20.7 | T10: -24 | U10: -28.2 | V10: -34.8 | W10: -33 | X10: -20.8 | Y10: -20.8 | Z10: -25.1 | AA10: -46.3 | AB10: -18 | AC10: -27.8 | AD10: -34 | AE10: -26.9 | AF10: -38 | AG10: -32 | AH10: -31.1 | AI10: -38.6 | AJ10: -29.1 | AK10: -53.8 | AL10: -39.3 | AM10: -51.3 | AN10: -20 | AO10: -48.3 | AP10: -28.4 | AQ10: -30 | AR10: -17.1 | AS10: -23.9 | AT10: -33 | AU10: -33.6 | AV10: -38 | AW10: -22.9 | AX10: -35 | AY10: -33 | AZ10: -40 | BA10: -22.6 | BB10: -31.3 | BC10: -22.6 | BD10: -17.5 | BE10: -17.5 | BF10: -17.5 | BG10: -27.1 | BH10: -27.1 | BI10: -27.1 | BJ10: -28.5 | BK10: -26.2 | BL10: -28.5 | BM10: -22 | BN10: -24.7 | BO10: -32.2 | BP10: -32.2 | BQ10: -18.2 | BR10: -32.2 | BS10: -34.7 | BT10: -33.9 | BU10: -16
A11: DG MOLAX | B11: -20.6 | C11: -29 | D11: -31.7 | E11: -22 | F11: -17.9 | G11: -26.3 | H11: -29 | I11: -29 | J11: -31.2 | K11: -30.7 | L11: -40 | M11: -40 | N11: -30.7 | O11: -37.5 | P11: -23 | Q11: -19.4 | R11: -22.5 | S11: -20.7 | T11: -24 | U11: -28.2 | V11: -34.8 | W11: -33 | X11: -20.8 | Y11: -20.8 | Z11: -25.1 | AA11: -46.3 | AB11: -18 | AC11: -27.8 | AD11: -34 | AE11: -26.9 | AF11: -38 | AG11: -32 | AH11: -31.1 | AI11: -38.6 | AJ11: -29.1 | AK11: -53.8 | AL11: -39.3 | AM11: -51.3 | AN11: -20 | AO11: -48.3 | AP11: -28.4 | AQ11: -30 | AR11: -17.1 | AS11: -23.9 | AT11: -33 | AU11: -33.6 | AV11: -38 | AW11: -22.9 | AX11: -35 | AY11: -33 | AZ11: -40 | BA11: -22.6 | BB11: -31.3 | BC11: -22.6 | BD11: -17.5 | BE11: -17.5 | BF11: -17.5 | BG11: -27.1 | BH11: -27.1 | BI11: -27.1 | BJ11: -28.5 | BK11: -26.2 | BL11: -28.5 | BM11: -22 | BN11: -24.7 | BO11: -32.2 | BP11: -32.2 | BQ11: -18.2 | BR11: -32.2 | BS11: -34.7 | BT11: -33.9 | BU11: -16
A12: DG MOPP | B12: -20.6 | C12: -29 | D12: -31.7 | E12: -22 | F12: -17.9 | G12: -26.3 | H12: -29 | I12: -29 | J12: -31.2 | K12: -30.7 | L12: -40 | M12: -40 | N12: -30.7 | O12: -37.5 | P12: -23 | Q12: -19.4 | R12: -22.5 | S12: -20.7 | T12: -24 | U12: -28.2 | V12: -34.8 | W12: -33 | X12: -20.8 | Y12: -20.8 | Z12: -25.1 | AA12: -46.3 | AB12: -18 | AC12: -27.8 | AD12: -34 | AE12: -26.9 | AF12: -38 | AG12: -32 | AH12: -31.1 | AI12: -38.6 | AJ12: -29.1 | AK12: -53.8 | AL12: -39.3 | AM12: -51.3 | AN12: -20 | AO12: -48.3 | AP12: -28.4 | AQ12: -30 | AR12: -17.1 | AS12: -23.9 | AT12: -33 | AU12: -33.6 | AV12: -38 | AW12: -22.9 | AX12: -35 | AY12: -33 | AZ12: -40 | BA12: -22.6 | BB12: -31.3 | BC12: -22.6 | BD12: -17.5 | BE12: -17.5 | BF12: -17.5 | BG12: -27.1 | BH12: -27.1 | BI12: -27.1 | BJ12: -28.5 | BK12: -26.2 | BL12: -28.5 | BM12: -22 | BN12: -24.7 | BO12: -32.2 | BP12: -32.2 | BQ12: -18.2 | BR12: -32.2 | BS12: -34.7 | BT12: -33.9 | BU12: -16
A13: DG Neurogliaform | B13: -20.6 | C13: -29 | D13: -31.7 | E13: -22 | F13: -17.9 | G13: -26.3 | H13: -29 | I13: -29 | J13: -31.2 | K13: -30.7 | L13: -40 | M13: -40 | N13: -30.7 | O13: -37.5 | P13: -23 | Q13: -19.4 | R13: -22.5 | S13: -20.7 | T13: -24 | U13: -28.2 | V13: -34.8 | W13: -33 | X13: -20.8 | Y13: -20.8 | Z13: -25.1 | AA13: -46.3 | AB13: -18 | AC13: -27.8 | AD13: -34 | AE13: -26.9 | AF13: -38 | AG13: -32 | AH13: -31.1 | AI13: -38.6 | AJ13: -29.1 | AK13: -53.8 | AL13: -39.3 | AM13: -51.3 | AN13: -20 | AO13: -48.3 | AP13: -28.4 | AQ13: -30 | AR13: -17.1 | AS13: -23.9 | AT13: -33 | AU13: -33.6 | AV13: -38 | AW13: -22.9 | AX13: -35 | AY13: -33 | AZ13: -40 | BA13: -22.6 | BB13: -31.3 | BC13: -22.6 | BD13: -17.5 | BE13: -17.5 | BF13: -17.5 | BG13: -27.1 | BH13: -27.1 | BI13: -27.1 | BJ13: -28.5 | BK13: -26.2 | BL13: -28.5 | BM13: -22 | BN13: -24.7 | BO13: -32.2 | BP13: -32.2 | BQ13: -18.2 | BR13: -32.2 | BS13: -34.7 | BT13: -33.9 | BU13: -16
... A73: MEC LIII Superficial Trilayered Interneuron | B73: -20.6 | C73: -29 | D73: -31.7 | E73: -22 | F73: -17.9 | G73: -26.3 | H73: -29 | I73: -29 | J73: -31.2 | K73: -30.7 | L73: -40 | M73: -40 | N73: -30.7 | O73: -37.5 | P73: -23 | Q73: -19.4 | R73: -22.5 | S73: -20.7 | T73: -24 | U73: -28.2 | V73: -34.8 | W73: -33 | X73: -20.8 | Y73: -20.8 | Z73: -25.1 | AA73: -46.3 | AB73: -18 | AC73: -27.8 | AD73: -34 | AE73: -26.9 | AF73: -38 | AG73: -32 | AH73: -31.1 | AI73: -38.6 | AJ73: -29.1 | AK73: -53.8 | AL73: -39.3 | AM73: -51.3 | AN73: -20 | AO73: -48.3 | AP73: -28.4 | AQ73: -30 | AR73: -17.1 | AS73: -23.9 | AT73: -33 | AU73: -33.6 | AV73: -38 | AW73: -22.9 | AX73: -35 | AY73: -33 | AZ73: -40 | BA73: -22.6 | BB73: -31.3 | BC73: -22.6 | BD73: -17.5 | BE73: -17.5 | BF73: -17.5 | BG73: -27.1 | BH73: -27.1 | BI73: -27.1 | BJ73: -28.5 | BK73: -26.2 | BL73: -28.5 | BM73: -22 | BN73: -24.7 | BO73: -32.2 | BP73: -32.2 | BQ73: -18.2 | BR73: -32.2 | BS73: -34.7 | BT73: -33.9 | BU73: -16

Sheet 72_qi
A1: Neuron Type | B1: Mice
A2: DG Granule | B2: 394502
A3: DG Semilunar Granule | B3: 67090
A4: DG Mossy | B4: 10485
A5: DG AIPRIM | B5: 3509
A6: DG Axo Axonic | B6: 96
A7: DG Basket | B7: 661
A8: DG HICAP | B8: 342
A9: DG HIPP | B9: 2462
A10: DG HIPROM | B10: 4
A11: DG MOLAX | B11: 2223
A12: DG MOPP | B12: 155
A13: DG Neurogliaform | B13: 246
... A73: MEC LIII Superficial Trilayered Interneuron | B73: 986

Sheet 72_wij
A1: =72^2-COUNTIF(B2:BU73, 0) -> 1151 | B1: DG Granule | C1: DG Semilunar Granule | D1: DG Mossy | E1: DG AIPRIM | F1: DG Axo Axonic | G1: DG Basket | H1: DG HICAP | I1: DG HIPP | J1: DG HIPROM | K1: DG MOLAX | L1: DG MOPP | M1: DG Neurogliaform | N1: DG Total Molecular Layer | O1: CA3 Pyramidal | P1: CA3c Pyramidal | Q1: CA3 Granule | R1: CA3 Axo Axonic | S1: CA3 Basket | T1: CA3 LMR Targeting | U1: CA3 Lucidum ORAX | V1: CA3 Spiny Lucidum | W1: CA3 Mossy Fiber Associated ORDEN | X1: CA3 Trilaminar | Y1: CA2 Basket | Z1: CA2 Wide Arbor Basket | AA1: CA2 Bistratified | AB1: CA2 SP SR | AC1: CA1 Pyramidal | AD1: CA1 Radiatum Giant | AE1: CA1 Axo Axonic | AF1: CA1 Horizontal Axo Axonic | AG1: CA1 Basket | AH1: CA1 Basket CCK+ | AI1: CA1 Horizontal Basket | AJ1: CA1 Ivy | AK1: CA1 LMR | AL1: CA1 Neurogliaform | AM1: CA1 Neurogliaform Projecting | AN1: CA1 Recurrent O LM | AO1: CA1 O LMR | AP1: CA1 Oriens Alveus | AQ1: CA1 Oriens Bistratified | AR1: CA1 OR LM | AS1: CA1 Perforant Path Associated | AT1: CA1 Perforant Path Associated QuadD | AU1: CA1 Radiatum | AV1: CA1 R Receiving Apical Targeting | AW1: CA1 Schaffer Collateral Associated | AX1: CA1 SO SO | AY1: CA1 Trilaminar | AZ1: CA1 Radial Trilaminar | BA1: EC LI II Multipolar Pyramidal | BB1: EC LI II Pyramidal Fan | BC1: MEC LII III Pyramidal Multiform | BD1: MEC LII Oblique Pyramidal | BE1: MEC LII Stellate | BF1: EC LII III Pyramidal Tripolar | BG1: LEC LIII Multipolar Principal | BH1: EC LIII Pyramidal | BI1: LEC LIII Complex Pyramidal | BJ1: MEC LIII Complex Pyramidal | BK1: MEC LIII Bipolar Complex Pyramidal | BL1: EC LIII Stellate | BM1: EC LIII V Bipolar Pyramidal | BN1: EC LIV VI Deep Multipolar Principal | BO1: EC LV Deep Pyramidal | BP1: MEC LV Multipolar Pyramidal | BQ1: MEC LV Pyramidal | BR1: MEC LV Superficial Pyramidal | BS1: MEC LV VI Pyramidal Polymorphic | BT1: LEC LVI Multipolar Pyramidal | BU1: MEC LIII Superficial Trilayered Interneuron
A2: DG Granule | B2: ='72_cij'!B2*'72_gij'!B2*'72_taudij'!B2*'72_vij'!B2*'72_qi'!$B2 -> 0 | C2: ='72_cij'!C2*'72_gij'!C2*'72_taudij'!C2*'72_vij'!C2*'72_qi'!$B2 -> 0 | D2: ='72_cij'!D2*'72_gij'!D2*'72_taudij'!D2*'72_vij'!D2*'72_qi'!$B2 -> 1548576.2 | E2: ='72_cij'!E2*'72_gij'!E2*'72_taudij'!E2*'72_vij'!E2*'72_qi'!$B2 -> 896639.2 | F2: ='72_cij'!F2*'72_gij'!F2*'72_taudij'!F2*'72_vij'!F2*'72_qi'!$B2 -> 708529.95 | G2: ='72_cij'!G2*'72_gij'!G2*'72_taudij'!G2*'72_vij'!G2*'72_qi'!$B2 -> 381384.74 | H2: ='72_cij'!H2*'72_gij'!H2*'72_taudij'!H2*'72_vij'!H2*'72_qi'!$B2 -> 418316.07 | I2: ='72_cij'!I2*'72_gij'!I2*'72_taudij'!I2*'72_vij'!I2*'72_qi'!$B2 -> 826561.2 | ... BU2: ='72_cij'!BU2*'72_gij'!BU2*'72_taudij'!BU2*'72_vij'!BU2*'72_qi'!$B2 -> 0
A3: DG Semilunar Granule | B3: ='72_cij'!B3*'72_gij'!B3*'72_taudij'!B3*'72_vij'!B3*'72_qi'!$B3 -> 10939.478 | C3: ='72_cij'!C3*'72_gij'!C3*'72_taudij'!C3*'72_vij'!C3*'72_qi'!$B3 -> 10125.859 | D3: ='72_cij'!D3*'72_gij'!D3*'72_taudij'!D3*'72_vij'!D3*'72_qi'!$B3 -> 177762.27 | E3: ='72_cij'!E3*'72_gij'!E3*'72_taudij'!E3*'72_vij'!E3*'72_qi'!$B3 -> 175502.85 | F3: ='72_cij'!F3*'72_gij'!F3*'72_taudij'!F3*'72_vij'!F3*'72_qi'!$B3 -> 128067.62 | G3: ='72_cij'!G3*'72_gij'!G3*'72_taudij'!G3*'72_vij'!G3*'72_qi'!$B3 -> 90708.451 | H3: ='72_cij'!H3*'72_gij'!H3*'72_taudij'!H3*'72_vij'!H3*'72_qi'!$B3 -> 98020.436 | I3: ='72_cij'!I3*'72_gij'!I3*'72_taudij'!I3*'72_vij'!I3*'72_qi'!$B3 -> 92711.45 | ... BU3: ='72_cij'!BU3*'72_gij'!BU3*'72_taudij'!BU3*'72_vij'!BU3*'72_qi'!$B3 -> 0
A4: DG Mossy | B4: ='72_cij'!B4*'72_gij'!B4*'72_taudij'!B4*'72_vij'!B4*'72_qi'!$B4 -> 21695.055 | C4: ='72_cij'!C4*'72_gij'!C4*'72_taudij'!C4*'72_vij'!C4*'72_qi'!$B4 -> 12630.591 | D4: ='72_cij'!D4*'72_gij'!D4*'72_taudij'!D4*'72_vij'!D4*'72_qi'!$B4 -> 60388.298 | E4: ='72_cij'!E4*'72_gij'!E4*'72_taudij'!E4*'72_vij'!E4*'72_qi'!$B4 -> 63309.346 | F4: ='72_cij'!F4*'72_gij'!F4*'72_taudij'!F4*'72_vij'!F4*'72_qi'!$B4 -> 65354.974 | G4: ='72_cij'!G4*'72_gij'!G4*'72_taudij'!G4*'72_vij'!G4*'72_qi'!$B4 -> 44703.717 | H4: ='72_cij'!H4*'72_gij'!H4*'72_taudij'!H4*'72_vij'!H4*'72_qi'!$B4 -> 37769.105 | I4: ='72_cij'!I4*'72_gij'!I4*'72_taudij'!I4*'72_vij'!I4*'72_qi'!$B4 -> 35791.767 | ... BU4: ='72_cij'!BU4*'72_gij'!BU4*'72_taudij'!BU4*'72_vij'!BU4*'72_qi'!$B4 -> 0
A5: DG AIPRIM | B5: ='72_cij'!B5*'72_gij'!B5*'72_taudij'!B5*'72_vij'!B5*'72_qi'!$B5 -> -5198.7076 | C5: ='72_cij'!C5*'72_gij'!C5*'72_taudij'!C5*'72_vij'!C5*'72_qi'!$B5 -> -4221.6903 | D5: ='72_cij'!D5*'72_gij'!D5*'72_taudij'!D5*'72_vij'!D5*'72_qi'!$B5 -> -8299.5673 | E5: ='72_cij'!E5*'72_gij'!E5*'72_taudij'!E5*'72_vij'!E5*'72_qi'!$B5 -> -10954.134 | F5: ='72_cij'!F5*'72_gij'!F5*'72_taudij'!F5*'72_vij'!F5*'72_qi'!$B5 -> -7725.7449 | G5: ='72_cij'!G5*'72_gij'!G5*'72_taudij'!G5*'72_vij'!G5*'72_qi'!$B5 -> -8921.3063 | H5: ='72_cij'!H5*'72_gij'!H5*'72_taudij'!H5*'72_vij'!H5*'72_qi'!$B5 -> -8982.6208 | I5: ='72_cij'!I5*'72_gij'!I5*'72_taudij'!I5*'72_vij'!I5*'72_qi'!$B5 -> -4647.5908 | ... BU5: ='72_cij'!BU5*'72_gij'!BU5*'72_taudij'!BU5*'72_vij'!BU5*'72_qi'!$B5 -> 0
A6: DG Axo Axonic | B6: ='72_cij'!B6*'72_gij'!B6*'72_taudij'!B6*'72_vij'!B6*'72_qi'!$B6 -> -39.867543 | C6: ='72_cij'!C6*'72_gij'!C6*'72_taudij'!C6*'72_vij'!C6*'72_qi'!$B6 -> 0 | D6: ='72_cij'!D6*'72_gij'!D6*'72_taudij'!D6*'72_vij'!D6*'72_qi'!$B6 -> -1589.3227 | E6: ='72_cij'!E6*'72_gij'!E6*'72_taudij'!E6*'72_vij'!E6*'72_qi'!$B6 -> 0 | F6: ='72_cij'!F6*'72_gij'!F6*'72_taudij'!F6*'72_vij'!F6*'72_qi'!$B6 -> 0 | G6: ='72_cij'!G6*'72_gij'!G6*'72_taudij'!G6*'72_vij'!G6*'72_qi'!$B6 -> 0 | H6: ='72_cij'!H6*'72_gij'!H6*'72_taudij'!H6*'72_vij'!H6*'72_qi'!$B6 -> 0 | I6: ='72_cij'!I6*'72_gij'!I6*'72_taudij'!I6*'72_vij'!I6*'72_qi'!$B6 -> 0 | ... BU6: ='72_cij'!BU6*'72_gij'!BU6*'72_taudij'!BU6*'72_vij'!BU6*'72_qi'!$B6 -> 0
A7: DG Basket | B7: ='72_cij'!B7*'72_gij'!B7*'72_taudij'!B7*'72_vij'!B7*'72_qi'!$B7 -> -30832.191 | C7: ='72_cij'!C7*'72_gij'!C7*'72_taudij'!C7*'72_vij'!C7*'72_qi'!$B7 -> 0 | D7: ='72_cij'!D7*'72_gij'!D7*'72_taudij'!D7*'72_vij'!D7*'72_qi'!$B7 -> 0 | E7: ='72_cij'!E7*'72_gij'!E7*'72_taudij'!E7*'72_vij'!E7*'72_qi'!$B7 -> 0 | F7: ='72_cij'!F7*'72_gij'!F7*'72_taudij'!F7*'72_vij'!F7*'72_qi'!$B7 -> -16791.653 | G7: ='72_cij'!G7*'72_gij'!G7*'72_taudij'!G7*'72_vij'!G7*'72_qi'!$B7 -> -21608.003 | H7: ='72_cij'!H7*'72_gij'!H7*'72_taudij'!H7*'72_vij'!H7*'72_qi'!$B7 -> -21886.277 | I7: ='72_cij'!I7*'72_gij'!I7*'72_taudij'!I7*'72_vij'!I7*'72_qi'!$B7 -> -23172.688 | ... BU7: ='72_cij'!BU7*'72_gij'!BU7*'72_taudij'!BU7*'72_vij'!BU7*'72_qi'!$B7 -> 0
A8: DG HICAP | B8: ='72_cij'!B8*'72_gij'!B8*'72_taudij'!B8*'72_vij'!B8*'72_qi'!$B8 -> -125.96014 | C8: ='72_cij'!C8*'72_gij'!C8*'72_taudij'!C8*'72_vij'!C8*'72_qi'!$B8 -> -103.01006 | D8: ='72_cij'!D8*'72_gij'!D8*'72_taudij'!D8*'72_vij'!D8*'72_qi'!$B8 -> 0 | E8: ='72_cij'!E8*'72_gij'!E8*'72_taudij'!E8*'72_vij'!E8*'72_qi'!$B8 -> -70.682864 | F8: ='72_cij'!F8*'72_gij'!F8*'72_taudij'!F8*'72_vij'!F8*'72_qi'!$B8 -> -67.328883 | G8: ='72_cij'!G8*'72_gij'!G8*'72_taudij'!G8*'72_vij'!G8*'72_qi'!$B8 -> -74.92935 | H8: ='72_cij'!H8*'72_gij'!H8*'72_taudij'!H8*'72_vij'!H8*'72_qi'!$B8 -> -63.955006 | I8: ='72_cij'!I8*'72_gij'!I8*'72_taudij'!I8*'72_vij'!I8*'72_qi'!$B8 -> 0 | ... BU8: ='72_cij'!BU8*'72_gij'!BU8*'72_taudij'!BU8*'72_vij'!BU8*'72_qi'!$B8 -> 0
A9: DG HIPP | B9: ='72_cij'!B9*'72_gij'!B9*'72_taudij'!B9*'72_vij'!B9*'72_qi'!$B9 -> -4519.9657 | C9: ='72_cij'!C9*'72_gij'!C9*'72_taudij'!C9*'72_vij'!C9*'72_qi'!$B9 -> -4421.7588 | D9: ='72_cij'!D9*'72_gij'!D9*'72_taudij'!D9*'72_vij'!D9*'72_qi'!$B9 -> 0 | E9: ='72_cij'!E9*'72_gij'!E9*'72_taudij'!E9*'72_vij'!E9*'72_qi'!$B9 -> -2244.4834 | F9: ='72_cij'!F9*'72_gij'!F9*'72_taudij'!F9*'72_vij'!F9*'72_qi'!$B9 -> -3199.1352 | G9: ='72_cij'!G9*'72_gij'!G9*'72_taudij'!G9*'72_vij'!G9*'72_qi'!$B9 -> -3295.453 | H9: ='72_cij'!H9*'72_gij'!H9*'72_taudij'!H9*'72_vij'!H9*'72_qi'!$B9 -> -2376.6098 | I9: ='72_cij'!I9*'72_gij'!I9*'72_taudij'!I9*'72_vij'!I9*'72_qi'!$B9 -> 0 | ... BU9: ='72_cij'!BU9*'72_gij'!BU9*'72_taudij'!BU9*'72_vij'!BU9*'72_qi'!$B9 -> 0
A10: DG HIPROM | B10: ='72_cij'!B10*'72_gij'!B10*'72_taudij'!B10*'72_vij'!B10*'72_qi'!$B10 -> -7.19789 | C10: ='72_cij'!C10*'72_gij'!C10*'72_taudij'!C10*'72_vij'!C10*'72_qi'!$B10 -> -7.0839118 | D10: ='72_cij'!D10*'72_gij'!D10*'72_taudij'!D10*'72_vij'!D10*'72_qi'!$B10 -> -10.870058 | E10: ='72_cij'!E10*'72_gij'!E10*'72_taudij'!E10*'72_vij'!E10*'72_qi'!$B10 -> -16.437965 | F10: ='72_cij'!F10*'72_gij'!F10*'72_taudij'!F10*'72_vij'!F10*'72_qi'!$B10 -> -12.128599 | G10: ='72_cij'!G10*'72_gij'!G10*'72_taudij'!G10*'72_vij'!G10*'72_qi'!$B10 -> -13.702804 | H10: ='72_cij'!H10*'72_gij'!H10*'72_taudij'!H10*'72_vij'!H10*'72_qi'!$B10 -> -13.406069 | I10: ='72_cij'!I10*'72_gij'!I10*'72_taudij'!I10*'72_vij'!I10*'72_qi'!$B10 -> -6.4807574 | ... BU10: ='72_cij'!BU10*'72_gij'!BU10*'72_taudij'!BU10*'72_vij'!BU10*'72_qi'!$B10 -> 0
A11: DG MOLAX | B11: ='72_cij'!B11*'72_gij'!B11*'72_taudij'!B11*'72_vij'!B11*'72_qi'!$B11 -> -3449.7923 | C11: ='72_cij'!C11*'72_gij'!C11*'72_taudij'!C11*'72_vij'!C11*'72_qi'!$B11 -> -3165.3755 | D11: ='72_cij'!D11*'72_gij'!D11*'72_taudij'!D11*'72_vij'!D11*'72_qi'!$B11 -> 0 | E11: ='72_cij'!E11*'72_gij'!E11*'72_taudij'!E11*'72_vij'!E11*'72_qi'!$B11 -> -1899.0559 | F11: ='72_cij'!F11*'72_gij'!F11*'72_taudij'!F11*'72_vij'!F11*'72_qi'!$B11 -> -2035.0466 | G11: ='72_cij'!G11*'72_gij'!G11*'72_taudij'!G11*'72_vij'!G11*'72_qi'!$B11 -> -2118.6821 | H11: ='72_cij'!H11*'72_gij'!H11*'72_taudij'!H11*'72_vij'!H11*'72_qi'!$B11 -> -2023.699 | I11: ='72_cij'!I11*'72_gij'!I11*'72_taudij'!I11*'72_vij'!I11*'72_qi'!$B11 -> 0 | ... BU11: ='72_cij'!BU11*'72_gij'!BU11*'72_taudij'!BU11*'72_vij'!BU11*'72_qi'!$B11 -> 0
A12: DG MOPP | B12: ='72_cij'!B12*'72_gij'!B12*'72_taudij'!B12*'72_vij'!B12*'72_qi'!$B12 -> -141.2253 | C12: ='72_cij'!C12*'72_gij'!C12*'72_taudij'!C12*'72_vij'!C12*'72_qi'!$B12 -> -130.09503 | D12: ='72_cij'!D12*'72_gij'!D12*'72_taudij'!D12*'72_vij'!D12*'72_qi'!$B12 -> 0 | E12: ='72_cij'!E12*'72_gij'!E12*'72_taudij'!E12*'72_vij'!E12*'72_qi'!$B12 -> -76.562893 | F12: ='72_cij'!F12*'72_gij'!F12*'72_taudij'!F12*'72_vij'!F12*'72_qi'!$B12 -> -87.67445 | G12: ='72_cij'!G12*'72_gij'!G12*'72_taudij'!G12*'72_vij'!G12*'72_qi'!$B12 -> -89.793189 | H12: ='72_cij'!H12*'72_gij'!H12*'72_taudij'!H12*'72_vij'!H12*'72_qi'!$B12 -> -74.882977 | I12: ='72_cij'!I12*'72_gij'!I12*'72_taudij'!I12*'72_vij'!I12*'72_qi'!$B12 -> 0 | ... BU12: ='72_cij'!BU12*'72_gij'!BU12*'72_taudij'!BU12*'72_vij'!BU12*'72_qi'!$B12 -> 0
A13: DG Neurogliaform | B13: ='72_cij'!B13*'72_gij'!B13*'72_taudij'!B13*'72_vij'!B13*'72_qi'!$B13 -> -48.706768 | C13: ='72_cij'!C13*'72_gij'!C13*'72_taudij'!C13*'72_vij'!C13*'72_qi'!$B13 -> -52.29438 | D13: ='72_cij'!D13*'72_gij'!D13*'72_taudij'!D13*'72_vij'!D13*'72_qi'!$B13 -> 0 | E13: ='72_cij'!E13*'72_gij'!E13*'72_taudij'!E13*'72_vij'!E13*'72_qi'!$B13 -> -16.4847 | F13: ='72_cij'!F13*'72_gij'!F13*'72_taudij'!F13*'72_vij'!F13*'72_qi'!$B13 -> -39.49973 | G13: ='72_cij'!G13*'72_gij'!G13*'72_taudij'!G13*'72_vij'!G13*'72_qi'!$B13 -> -19.153461 | H13: ='72_cij'!H13*'72_gij'!H13*'72_taudij'!H13*'72_vij'!H13*'72_qi'!$B13 -> -16.752275 | I13: ='72_cij'!I13*'72_gij'!I13*'72_taudij'!I13*'72_vij'!I13*'72_qi'!$B13 -> 0 | ... BU13: ='72_cij'!BU13*'72_gij'!BU13*'72_taudij'!BU13*'72_vij'!BU13*'72_qi'!$B13 -> 0
... A73: MEC LIII Superficial Trilayered Interneuron | B73: ='72_cij'!B73*'72_gij'!B73*'72_taudij'!B73*'72_vij'!B73*'72_qi'!$B73 -> 0 | C73: ='72_cij'!C73*'72_gij'!C73*'72_taudij'!C73*'72_vij'!C73*'72_qi'!$B73 -> 0 | D73: ='72_cij'!D73*'72_gij'!D73*'72_taudij'!D73*'72_vij'!D73*'72_qi'!$B73 -> 0 | E73: ='72_cij'!E73*'72_gij'!E73*'72_taudij'!E73*'72_vij'!E73*'72_qi'!$B73 -> 0 | F73: ='72_cij'!F73*'72_gij'!F73*'72_taudij'!F73*'72_vij'!F73*'72_qi'!$B73 -> 0 | G73: ='72_cij'!G73*'72_gij'!G73*'72_taudij'!G73*'72_vij'!G73*'72_qi'!$B73 -> 0 | H73: ='72_cij'!H73*'72_gij'!H73*'72_taudij'!H73*'72_vij'!H73*'72_qi'!$B73 -> 0 | I73: ='72_cij'!I73*'72_gij'!I73*'72_taudij'!I73*'72_vij'!I73*'72_qi'!$B73 -> 0 | ... BU73: ='72_cij'!BU73*'72_gij'!BU73*'72_taudij'!BU73*'72_vij'!BU73*'72_qi'!$B73 -> -1330.8922
